Workbook

Sheet Event_Girdi
A1: Event_ID | B1: Event_Adi | C1: Baslangic | D1: Bitis | E1: Priority | F1: Deeplink_Pinned | G1: Aktif_mi | H1: Deeplink_Sira
A2: E_DL | B2: Deeplink Decor | C2: 45992 | D2: 46037 | E2: 99 | F2: Evet | G2: Evet | H2: =IF(F2="Evet";0;1)
A3: E_TG | B3: Thanksgiving | C3: 46006 | D3: 46016 | E3: 1 | F3: Hayir | G3: Evet | H3: =IF(F3="Evet";0;1)
A4: E_XMAS | B4: Christmas | C4: 45992 | D4: 46022 | E4: 2 | F4: Hayir | G4: Evet | H4: =IF(F4="Evet";0;1)
A5: E_UA_JAN | B5: UA Decor Jan | C5: 46023 | D5: 46032 | E5: 5 | F5: Hayir | G5: Evet | H5: =IF(F5="Evet";0;1)
H6: =IF(F6="";"";IF(F6="Evet";0;1))
H7: =IF(F7="";"";IF(F7="Evet";0;1))
H8: =IF(F8="";"";IF(F8="Evet";0;1))
H9: =IF(F9="";"";IF(F9="Evet";0;1))
H10: =IF(F10="";"";IF(F10="Evet";0;1))
H11: =IF(F11="";"";IF(F11="Evet";0;1))
H12: =IF(F12="";"";IF(F12="Evet";0;1))
H13: =IF(F13="";"";IF(F13="Evet";0;1))
H14: =IF(F14="";"";IF(F14="Evet";0;1))
H15: =IF(F15="";"";IF(F15="Evet";0;1))
H16: =IF(F16="";"";IF(F16="Evet";0;1))
H17: =IF(F17="";"";IF(F17="Evet";0;1))
... H60: =IF(F60="";"";IF(F60="Evet";0;1))

Sheet Hafta_Ozet
A1: Hafta_No | B1: Hafta_Baslangic | C1: Hafta_Bitis | D1: Tarih_Araligi | E1: Aktif_Eventler | F1: Cakisma_Max | G1: Winner_Organik | H1: Winner_Deeplink | I1: Queue_Hafta_Basi | J1: Durum
A2: =IF(B2="";"";"W"&(ROW()-1)) | B2: =IFERROR(MIN(FILTER(Event_Girdi!$C$2:$C;Event_Girdi!$G$2:$G="Evet"))-WEEKDAY(MIN(FILTER(Event_Girdi!$C$2:$C;Event_Girdi!$G$2:$G="Evet"));2)+1;"") | C2: =IF(B2="";"";B2+6) | D2: =IF(B2="";"";TEXT(B2;"dd mmm")&" - "&TEXT(C2;"dd mmm")) | E2: =IF(B2="";"";IFERROR(TEXTJOIN("; ";TRUE;FILTER(Event_Girdi!$A$2:$A;Event_Girdi!$G$2:$G="Evet";Event_Girdi!$C$2:$C<=C2;Event_Girdi!$D$2:$D>=B2));"")) | F2: =IF(B2="";"";MAX(COUNTIFS(Event_Girdi!$C$2:$C;"<="&B2;Event_Girdi!$D$2:$D;">="&B2;Event_Girdi!$G$2:$G;"Evet");COUNTIFS(Event_Girdi!$C$2:$C;"<="&B2+1;Event_Girdi!$D$2:$D;">="&B2+1;Event_Girdi!$G$2:$G;"Evet");COUNTIFS(Event_Girdi!$C$2:$C;"<="&B2+2;Event_Girdi!$D$2:$D;">="&B2+2;Event_Girdi!$G$2:$G;"Evet");COUNTIFS(Event_Girdi!$C$2:$C;"<="&B2+3;Event_Girdi!$D$2:$D;">="&B2+3;Event_Girdi!$G$2:$G;"Evet");COUNTIFS(Event_Girdi!$C$2:$C;"<="&B2+4;Event_Girdi!$D$2:$D;">="&B2+4;Event_Girdi!$G$2:$G;"Evet");COUNTIFS(Event_Girdi!$C$2:$C;"<="&B2+5;Event_Girdi!$D$2:$D;">="&B2+5;Event_Girdi!$G$2:$G;"Evet");COUNTIFS(Event_Girdi!$C$2:$C;"<="&B2+6;Event_Girdi!$D$2:$D;">="&B2+6;Event_Girdi!$G$2:$G;"Evet"))) | G2: =IF(B2="";"";IFERROR(INDEX(SORT(FILTER(Event_Girdi!$A$2:$E;Event_Girdi!$G$2:$G="Evet";Event_Girdi!$C$2:$C<=B2;Event_Girdi!$D$2:$D>=B2);5;TRUE;3;TRUE;1;TRUE);1;1);"")) | H2: =IF(B2="";"";IFERROR(INDEX(SORT(FILTER(Event_Girdi!$A$2:$F;Event_Girdi!$G$2:$G="Evet";Event_Girdi!$F$2:$F="Evet";Event_Girdi!$C$2:$C<=B2;Event_Girdi!$D$2:$D>=B2);3;TRUE;1;TRUE);1;1);G2)) | I2: =IF(B2="";"";IFERROR(TEXTJOIN(" > ";TRUE;INDEX(SORT(FILTER(Event_Girdi!$A$2:$H;Event_Girdi!$G$2:$G="Evet";Event_Girdi!$C$2:$C<=B2;Event_Girdi!$D$2:$D>=B2);8;TRUE;5;TRUE;3;TRUE;1;TRUE);;1));"")) | J2: =IF(B2="";"";IF(F2>1;"Cakisiyor";"Normal"))
A3: =IF(B3="";"";"W"&(ROW()-1)) | B3: =IF(B2="";"";IF(B2+7<=MAX(FILTER(Event_Girdi!$D$2:$D;Event_Girdi!$G$2:$G="Evet"))+6;B2+7;"")) | C3: =IF(B3="";"";B3+6) | D3: =IF(B3="";"";TEXT(B3;"dd mmm")&" - "&TEXT(C3;"dd mmm")) | E3: =IF(B3="";"";IFERROR(TEXTJOIN("; ";TRUE;FILTER(Event_Girdi!$A$2:$A;Event_Girdi!$G$2:$G="Evet";Event_Girdi!$C$2:$C<=C3;Event_Girdi!$D$2:$D>=B3));"")) | F3: =IF(B3="";"";MAX(COUNTIFS(Event_Girdi!$C$2:$C;"<="&B3;Event_Girdi!$D$2:$D;">="&B3;Event_Girdi!$G$2:$G;"Evet");COUNTIFS(Event_Girdi!$C$2:$C;"<="&B3+1;Event_Girdi!$D$2:$D;">="&B3+1;Event_Girdi!$G$2:$G;"Evet");COUNTIFS(Event_Girdi!$C$2:$C;"<="&B3+2;Event_Girdi!$D$2:$D;">="&B3+2;Event_Girdi!$G$2:$G;"Evet");COUNTIFS(Event_Girdi!$C$2:$C;"<="&B3+3;Event_Girdi!$D$2:$D;">="&B3+3;Event_Girdi!$G$2:$G;"Evet");COUNTIFS(Event_Girdi!$C$2:$C;"<="&B3+4;Event_Girdi!$D$2:$D;">="&B3+4;Event_Girdi!$G$2:$G;"Evet");COUNTIFS(Event_Girdi!$C$2:$C;"<="&B3+5;Event_Girdi!$D$2:$D;">="&B3+5;Event_Girdi!$G$2:$G;"Evet");COUNTIFS(Event_Girdi!$C$2:$C;"<="&B3+6;Event_Girdi!$D$2:$D;">="&B3+6;Event_Girdi!$G$2:$G;"Evet"))) | G3: =IF(B3="";"";IFERROR(INDEX(SORT(FILTER(Event_Girdi!$A$2:$E;Event_Girdi!$G$2:$G="Evet";Event_Girdi!$C$2:$C<=B3;Event_Girdi!$D$2:$D>=B3);5;TRUE;3;TRUE;1;TRUE);1;1);"")) | H3: =IF(B3="";"";IFERROR(INDEX(SORT(FILTER(Event_Girdi!$A$2:$F;Event_Girdi!$G$2:$G="Evet";Event_Girdi!$F$2:$F="Evet";Event_Girdi!$C$2:$C<=B3;Event_Girdi!$D$2:$D>=B3);3;TRUE;1;TRUE);1;1);G3)) | I3: =IF(B3="";"";IFERROR(TEXTJOIN(" > ";TRUE;INDEX(SORT(FILTER(Event_Girdi!$A$2:$H;Event_Girdi!$G$2:$G="Evet";Event_Girdi!$C$2:$C<=B3;Event_Girdi!$D$2:$D>=B3);8;TRUE;5;TRUE;3;TRUE;1;TRUE);;1));"")) | J3: =IF(B3="";"";IF(F3>1;"Cakisiyor";"Normal"))
A4: =IF(B4="";"";"W"&(ROW()-1)) | B4: =IF(B3="";"";IF(B3+7<=MAX(FILTER(Event_Girdi!$D$2:$D;Event_Girdi!$G$2:$G="Evet"))+6;B3+7;"")) | C4: =IF(B4="";"";B4+6) | D4: =IF(B4="";"";TEXT(B4;"dd mmm")&" - "&TEXT(C4;"dd mmm")) | E4: =IF(B4="";"";IFERROR(TEXTJOIN("; ";TRUE;FILTER(Event_Girdi!$A$2:$A;Event_Girdi!$G$2:$G="Evet";Event_Girdi!$C$2:$C<=C4;Event_Girdi!$D$2:$D>=B4));"")) | F4: =IF(B4="";"";MAX(COUNTIFS(Event_Girdi!$C$2:$C;"<="&B4;Event_Girdi!$D$2:$D;">="&B4;Event_Girdi!$G$2:$G;"Evet");COUNTIFS(Event_Girdi!$C$2:$C;"<="&B4+1;Event_Girdi!$D$2:$D;">="&B4+1;Event_Girdi!$G$2:$G;"Evet");COUNTIFS(Event_Girdi!$C$2:$C;"<="&B4+2;Event_Girdi!$D$2:$D;">="&B4+2;Event_Girdi!$G$2:$G;"Evet");COUNTIFS(Event_Girdi!$C$2:$C;"<="&B4+3;Event_Girdi!$D$2:$D;">="&B4+3;Event_Girdi!$G$2:$G;"Evet");COUNTIFS(Event_Girdi!$C$2:$C;"<="&B4+4;Event_Girdi!$D$2:$D;">="&B4+4;Event_Girdi!$G$2:$G;"Evet");COUNTIFS(Event_Girdi!$C$2:$C;"<="&B4+5;Event_Girdi!$D$2:$D;">="&B4+5;Event_Girdi!$G$2:$G;"Evet");COUNTIFS(Event_Girdi!$C$2:$C;"<="&B4+6;Event_Girdi!$D$2:$D;">="&B4+6;Event_Girdi!$G$2:$G;"Evet"))) | G4: =IF(B4="";"";IFERROR(INDEX(SORT(FILTER(Event_Girdi!$A$2:$E;Event_Girdi!$G$2:$G="Evet";Event_Girdi!$C$2:$C<=B4;Event_Girdi!$D$2:$D>=B4);5;TRUE;3;TRUE;1;TRUE);1;1);"")) | H4: =IF(B4="";"";IFERROR(INDEX(SORT(FILTER(Event_Girdi!$A$2:$F;Event_Girdi!$G$2:$G="Evet";Event_Girdi!$F$2:$F="Evet";Event_Girdi!$C$2:$C<=B4;Event_Girdi!$D$2:$D>=B4);3;TRUE;1;TRUE);1;1);G4)) | I4: =IF(B4="";"";IFERROR(TEXTJOIN(" > ";TRUE;INDEX(SORT(FILTER(Event_Girdi!$A$2:$H;Event_Girdi!$G$2:$G="Evet";Event_Girdi!$C$2:$C<=B4;Event_Girdi!$D$2:$D>=B4);8;TRUE;5;TRUE;3;TRUE;1;TRUE);;1));"")) | J4: =IF(B4="";"";IF(F4>1;"Cakisiyor";"Normal"))
A5: =IF(B5="";"";"W"&(ROW()-1)) | B5: =IF(B4="";"";IF(B4+7<=MAX(FILTER(Event_Girdi!$D$2:$D;Event_Girdi!$G$2:$G="Evet"))+6;B4+7;"")) | C5: =IF(B5="";"";B5+6) | D5: =IF(B5="";"";TEXT(B5;"dd mmm")&" - "&TEXT(C5;"dd mmm")) | E5: =IF(B5="";"";IFERROR(TEXTJOIN("; ";TRUE;FILTER(Event_Girdi!$A$2:$A;Event_Girdi!$G$2:$G="Evet";Event_Girdi!$C$2:$C<=C5;Event_Girdi!$D$2:$D>=B5));"")) | F5: =IF(B5="";"";MAX(COUNTIFS(Event_Girdi!$C$2:$C;"<="&B5;Event_Girdi!$D$2:$D;">="&B5;Event_Girdi!$G$2:$G;"Evet");COUNTIFS(Event_Girdi!$C$2:$C;"<="&B5+1;Event_Girdi!$D$2:$D;">="&B5+1;Event_Girdi!$G$2:$G;"Evet");COUNTIFS(Event_Girdi!$C$2:$C;"<="&B5+2;Event_Girdi!$D$2:$D;">="&B5+2;Event_Girdi!$G$2:$G;"Evet");COUNTIFS(Event_Girdi!$C$2:$C;"<="&B5+3;Event_Girdi!$D$2:$D;">="&B5+3;Event_Girdi!$G$2:$G;"Evet");COUNTIFS(Event_Girdi!$C$2:$C;"<="&B5+4;Event_Girdi!$D$2:$D;">="&B5+4;Event_Girdi!$G$2:$G;"Evet");COUNTIFS(Event_Girdi!$C$2:$C;"<="&B5+5;Event_Girdi!$D$2:$D;">="&B5+5;Event_Girdi!$G$2:$G;"Evet");COUNTIFS(Event_Girdi!$C$2:$C;"<="&B5+6;Event_Girdi!$D$2:$D;">="&B5+6;Event_Girdi!$G$2:$G;"Evet"))) | G5: =IF(B5="";"";IFERROR(INDEX(SORT(FILTER(Event_Girdi!$A$2:$E;Event_Girdi!$G$2:$G="Evet";Event_Girdi!$C$2:$C<=B5;Event_Girdi!$D$2:$D>=B5);5;TRUE;3;TRUE;1;TRUE);1;1);"")) | H5: =IF(B5="";"";IFERROR(INDEX(SORT(FILTER(Event_Girdi!$A$2:$F;Event_Girdi!$G$2:$G="Evet";Event_Girdi!$F$2:$F="Evet";Event_Girdi!$C$2:$C<=B5;Event_Girdi!$D$2:$D>=B5);3;TRUE;1;TRUE);1;1);G5)) | I5: =IF(B5="";"";IFERROR(TEXTJOIN(" > ";TRUE;INDEX(SORT(FILTER(Event_Girdi!$A$2:$H;Event_Girdi!$G$2:$G="Evet";Event_Girdi!$C$2:$C<=B5;Event_Girdi!$D$2:$D>=B5);8;TRUE;5;TRUE;3;TRUE;1;TRUE);;1));"")) | J5: =IF(B5="";"";IF(F5>1;"Cakisiyor";"Normal"))
A6: =IF(B6="";"";"W"&(ROW()-1)) | B6: =IF(B5="";"";IF(B5+7<=MAX(FILTER(Event_Girdi!$D$2:$D;Event_Girdi!$G$2:$G="Evet"))+6;B5+7;"")) | C6: =IF(B6="";"";B6+6) | D6: =IF(B6="";"";TEXT(B6;"dd mmm")&" - "&TEXT(C6;"dd mmm")) | E6: =IF(B6="";"";IFERROR(TEXTJOIN("; ";TRUE;FILTER(Event_Girdi!$A$2:$A;Event_Girdi!$G$2:$G="Evet";Event_Girdi!$C$2:$C<=C6;Event_Girdi!$D$2:$D>=B6));"")) | F6: =IF(B6="";"";MAX(COUNTIFS(Event_Girdi!$C$2:$C;"<="&B6;Event_Girdi!$D$2:$D;">="&B6;Event_Girdi!$G$2:$G;"Evet");COUNTIFS(Event_Girdi!$C$2:$C;"<="&B6+1;Event_Girdi!$D$2:$D;">="&B6+1;Event_Girdi!$G$2:$G;"Evet");COUNTIFS(Event_Girdi!$C$2:$C;"<="&B6+2;Event_Girdi!$D$2:$D;">="&B6+2;Event_Girdi!$G$2:$G;"Evet");COUNTIFS(Event_Girdi!$C$2:$C;"<="&B6+3;Event_Girdi!$D$2:$D;">="&B6+3;Event_Girdi!$G$2:$G;"Evet");COUNTIFS(Event_Girdi!$C$2:$C;"<="&B6+4;Event_Girdi!$D$2:$D;">="&B6+4;Event_Girdi!$G$2:$G;"Evet");COUNTIFS(Event_Girdi!$C$2:$C;"<="&B6+5;Event_Girdi!$D$2:$D;">="&B6+5;Event_Girdi!$G$2:$G;"Evet");COUNTIFS(Event_Girdi!$C$2:$C;"<="&B6+6;Event_Girdi!$D$2:$D;">="&B6+6;Event_Girdi!$G$2:$G;"Evet"))) | G6: =IF(B6="";"";IFERROR(INDEX(SORT(FILTER(Event_Girdi!$A$2:$E;Event_Girdi!$G$2:$G="Evet";Event_Girdi!$C$2:$C<=B6;Event_Girdi!$D$2:$D>=B6);5;TRUE;3;TRUE;1;TRUE);1;1);"")) | H6: =IF(B6="";"";IFERROR(INDEX(SORT(FILTER(Event_Girdi!$A$2:$F;Event_Girdi!$G$2:$G="Evet";Event_Girdi!$F$2:$F="Evet";Event_Girdi!$C$2:$C<=B6;Event_Girdi!$D$2:$D>=B6);3;TRUE;1;TRUE);1;1);G6)) | I6: =IF(B6="";"";IFERROR(TEXTJOIN(" > ";TRUE;INDEX(SORT(FILTER(Event_Girdi!$A$2:$H;Event_Girdi!$G$2:$G="Evet";Event_Girdi!$C$2:$C<=B6;Event_Girdi!$D$2:$D>=B6);8;TRUE;5;TRUE;3;TRUE;1;TRUE);;1));"")) | J6: =IF(B6="";"";IF(F6>1;"Cakisiyor";"Normal"))
A7: =IF(B7="";"";"W"&(ROW()-1)) | B7: =IF(B6="";"";IF(B6+7<=MAX(FILTER(Event_Girdi!$D$2:$D;Event_Girdi!$G$2:$G="Evet"))+6;B6+7;"")) | C7: =IF(B7="";"";B7+6) | D7: =IF(B7="";"";TEXT(B7;"dd mmm")&" - "&TEXT(C7;"dd mmm")) | E7: =IF(B7="";"";IFERROR(TEXTJOIN("; ";TRUE;FILTER(Event_Girdi!$A$2:$A;Event_Girdi!$G$2:$G="Evet";Event_Girdi!$C$2:$C<=C7;Event_Girdi!$D$2:$D>=B7));"")) | F7: =IF(B7="";"";MAX(COUNTIFS(Event_Girdi!$C$2:$C;"<="&B7;Event_Girdi!$D$2:$D;">="&B7;Event_Girdi!$G$2:$G;"Evet");COUNTIFS(Event_Girdi!$C$2:$C;"<="&B7+1;Event_Girdi!$D$2:$D;">="&B7+1;Event_Girdi!$G$2:$G;"Evet");COUNTIFS(Event_Girdi!$C$2:$C;"<="&B7+2;Event_Girdi!$D$2:$D;">="&B7+2;Event_Girdi!$G$2:$G;"Evet");COUNTIFS(Event_Girdi!$C$2:$C;"<="&B7+3;Event_Girdi!$D$2:$D;">="&B7+3;Event_Girdi!$G$2:$G;"Evet");COUNTIFS(Event_Girdi!$C$2:$C;"<="&B7+4;Event_Girdi!$D$2:$D;">="&B7+4;Event_Girdi!$G$2:$G;"Evet");COUNTIFS(Event_Girdi!$C$2:$C;"<="&B7+5;Event_Girdi!$D$2:$D;">="&B7+5;Event_Girdi!$G$2:$G;"Evet");COUNTIFS(Event_Girdi!$C$2:$C;"<="&B7+6;Event_Girdi!$D$2:$D;">="&B7+6;Event_Girdi!$G$2:$G;"Evet"))) | G7: =IF(B7="";"";IFERROR(INDEX(SORT(FILTER(Event_Girdi!$A$2:$E;Event_Girdi!$G$2:$G="Evet";Event_Girdi!$C$2:$C<=B7;Event_Girdi!$D$2:$D>=B7);5;TRUE;3;TRUE;1;TRUE);1;1);"")) | H7: =IF(B7="";"";IFERROR(INDEX(SORT(FILTER(Event_Girdi!$A$2:$F;Event_Girdi!$G$2:$G="Evet";Event_Girdi!$F$2:$F="Evet";Event_Girdi!$C$2:$C<=B7;Event_Girdi!$D$2:$D>=B7);3;TRUE;1;TRUE);1;1);G7)) | I7: =IF(B7="";"";IFERROR(TEXTJOIN(" > ";TRUE;INDEX(SORT(FILTER(Event_Girdi!$A$2:$H;Event_Girdi!$G$2:$G="Evet";Event_Girdi!$C$2:$C<=B7;Event_Girdi!$D$2:$D>=B7);8;TRUE;5;TRUE;3;TRUE;1;TRUE);;1));"")) | J7: =IF(B7="";"";IF(F7>1;"Cakisiyor";"Normal"))
A8: =IF(B8="";"";"W"&(ROW()-1)) | B8: =IF(B7="";"";IF(B7+7<=MAX(FILTER(Event_Girdi!$D$2:$D;Event_Girdi!$G$2:$G="Evet"))+6;B7+7;"")) | C8: =IF(B8="";"";B8+6) | D8: =IF(B8="";"";TEXT(B8;"dd mmm")&" - "&TEXT(C8;"dd mmm")) | E8: =IF(B8="";"";IFERROR(TEXTJOIN("; ";TRUE;FILTER(Event_Girdi!$A$2:$A;Event_Girdi!$G$2:$G="Evet";Event_Girdi!$C$2:$C<=C8;Event_Girdi!$D$2:$D>=B8));"")) | F8: =IF(B8="";"";MAX(COUNTIFS(Event_Girdi!$C$2:$C;"<="&B8;Event_Girdi!$D$2:$D;">="&B8;Event_Girdi!$G$2:$G;"Evet");COUNTIFS(Event_Girdi!$C$2:$C;"<="&B8+1;Event_Girdi!$D$2:$D;">="&B8+1;Event_Girdi!$G$2:$G;"Evet");COUNTIFS(Event_Girdi!$C$2:$C;"<="&B8+2;Event_Girdi!$D$2:$D;">="&B8+2;Event_Girdi!$G$2:$G;"Evet");COUNTIFS(Event_Girdi!$C$2:$C;"<="&B8+3;Event_Girdi!$D$2:$D;">="&B8+3;Event_Girdi!$G$2:$G;"Evet");COUNTIFS(Event_Girdi!$C$2:$C;"<="&B8+4;Event_Girdi!$D$2:$D;">="&B8+4;Event_Girdi!$G$2:$G;"Evet");COUNTIFS(Event_Girdi!$C$2:$C;"<="&B8+5;Event_Girdi!$D$2:$D;">="&B8+5;Event_Girdi!$G$2:$G;"Evet");COUNTIFS(Event_Girdi!$C$2:$C;"<="&B8+6;Event_Girdi!$D$2:$D;">="&B8+6;Event_Girdi!$G$2:$G;"Evet"))) | G8: =IF(B8="";"";IFERROR(INDEX(SORT(FILTER(Event_Girdi!$A$2:$E;Event_Girdi!$G$2:$G="Evet";Event_Girdi!$C$2:$C<=B8;Event_Girdi!$D$2:$D>=B8);5;TRUE;3;TRUE;1;TRUE);1;1);"")) | H8: =IF(B8="";"";IFERROR(INDEX(SORT(FILTER(Event_Girdi!$A$2:$F;Event_Girdi!$G$2:$G="Evet";Event_Girdi!$F$2:$F="Evet";Event_Girdi!$C$2:$C<=B8;Event_Girdi!$D$2:$D>=B8);3;TRUE;1;TRUE);1;1);G8)) | I8: =IF(B8="";"";IFERROR(TEXTJOIN(" > ";TRUE;INDEX(SORT(FILTER(Event_Girdi!$A$2:$H;Event_Girdi!$G$2:$G="Evet";Event_Girdi!$C$2:$C<=B8;Event_Girdi!$D$2:$D>=B8);8;TRUE;5;TRUE;3;TRUE;1;TRUE);;1));"")) | J8: =IF(B8="";"";IF(F8>1;"Cakisiyor";"Normal"))
A9: =IF(B9="";"";"W"&(ROW()-1)) | B9: =IF(B8="";"";IF(B8+7<=MAX(FILTER(Event_Girdi!$D$2:$D;Event_Girdi!$G$2:$G="Evet"))+6;B8+7;"")) | C9: =IF(B9="";"";B9+6) | D9: =IF(B9="";"";TEXT(B9;"dd mmm")&" - "&TEXT(C9;"dd mmm")) | E9: =IF(B9="";"";IFERROR(TEXTJOIN("; ";TRUE;FILTER(Event_Girdi!$A$2:$A;Event_Girdi!$G$2:$G="Evet";Event_Girdi!$C$2:$C<=C9;Event_Girdi!$D$2:$D>=B9));"")) | F9: =IF(B9="";"";MAX(COUNTIFS(Event_Girdi!$C$2:$C;"<="&B9;Event_Girdi!$D$2:$D;">="&B9;Event_Girdi!$G$2:$G;"Evet");COUNTIFS(Event_Girdi!$C$2:$C;"<="&B9+1;Event_Girdi!$D$2:$D;">="&B9+1;Event_Girdi!$G$2:$G;"Evet");COUNTIFS(Event_Girdi!$C$2:$C;"<="&B9+2;Event_Girdi!$D$2:$D;">="&B9+2;Event_Girdi!$G$2:$G;"Evet");COUNTIFS(Event_Girdi!$C$2:$C;"<="&B9+3;Event_Girdi!$D$2:$D;">="&B9+3;Event_Girdi!$G$2:$G;"Evet");COUNTIFS(Event_Girdi!$C$2:$C;"<="&B9+4;Event_Girdi!$D$2:$D;">="&B9+4;Event_Girdi!$G$2:$G;"Evet");COUNTIFS(Event_Girdi!$C$2:$C;"<="&B9+5;Event_Girdi!$D$2:$D;">="&B9+5;Event_Girdi!$G$2:$G;"Evet");COUNTIFS(Event_Girdi!$C$2:$C;"<="&B9+6;Event_Girdi!$D$2:$D;">="&B9+6;Event_Girdi!$G$2:$G;"Evet"))) | G9: =IF(B9="";"";IFERROR(INDEX(SORT(FILTER(Event_Girdi!$A$2:$E;Event_Girdi!$G$2:$G="Evet";Event_Girdi!$C$2:$C<=B9;Event_Girdi!$D$2:$D>=B9);5;TRUE;3;TRUE;1;TRUE);1;1);"")) | H9: =IF(B9="";"";IFERROR(INDEX(SORT(FILTER(Event_Girdi!$A$2:$F;Event_Girdi!$G$2:$G="Evet";Event_Girdi!$F$2:$F="Evet";Event_Girdi!$C$2:$C<=B9;Event_Girdi!$D$2:$D>=B9);3;TRUE;1;TRUE);1;1);G9)) | I9: =IF(B9="";"";IFERROR(TEXTJOIN(" > ";TRUE;INDEX(SORT(FILTER(Event_Girdi!$A$2:$H;Event_Girdi!$G$2:$G="Evet";Event_Girdi!$C$2:$C<=B9;Event_Girdi!$D$2:$D>=B9);8;TRUE;5;TRUE;3;TRUE;1;TRUE);;1));"")) | J9: =IF(B9="";"";IF(F9>1;"Cakisiyor";"Normal"))
A10: =IF(B10="";"";"W"&(ROW()-1)) | B10: =IF(B9="";"";IF(B9+7<=MAX(FILTER(Event_Girdi!$D$2:$D;Event_Girdi!$G$2:$G="Evet"))+6;B9+7;"")) | C10: =IF(B10="";"";B10+6) | D10: =IF(B10="";"";TEXT(B10;"dd mmm")&" - "&TEXT(C10;"dd mmm")) | E10: =IF(B10="";"";IFERROR(TEXTJOIN("; ";TRUE;FILTER(Event_Girdi!$A$2:$A;Event_Girdi!$G$2:$G="Evet";Event_Girdi!$C$2:$C<=C10;Event_Girdi!$D$2:$D>=B10));"")) | F10: =IF(B10="";"";MAX(COUNTIFS(Event_Girdi!$C$2:$C;"<="&B10;Event_Girdi!$D$2:$D;">="&B10;Event_Girdi!$G$2:$G;"Evet");COUNTIFS(Event_Girdi!$C$2:$C;"<="&B10+1;Event_Girdi!$D$2:$D;">="&B10+1;Event_Girdi!$G$2:$G;"Evet");COUNTIFS(Event_Girdi!$C$2:$C;"<="&B10+2;Event_Girdi!$D$2:$D;">="&B10+2;Event_Girdi!$G$2:$G;"Evet");COUNTIFS(Event_Girdi!$C$2:$C;"<="&B10+3;Event_Girdi!$D$2:$D;">="&B10+3;Event_Girdi!$G$2:$G;"Evet");COUNTIFS(Event_Girdi!$C$2:$C;"<="&B10+4;Event_Girdi!$D$2:$D;">="&B10+4;Event_Girdi!$G$2:$G;"Evet");COUNTIFS(Event_Girdi!$C$2:$C;"<="&B10+5;Event_Girdi!$D$2:$D;">="&B10+5;Event_Girdi!$G$2:$G;"Evet");COUNTIFS(Event_Girdi!$C$2:$C;"<="&B10+6;Event_Girdi!$D$2:$D;">="&B10+6;Event_Girdi!$G$2:$G;"Evet"))) | G10: =IF(B10="";"";IFERROR(INDEX(SORT(FILTER(Event_Girdi!$A$2:$E;Event_Girdi!$G$2:$G="Evet";Event_Girdi!$C$2:$C<=B10;Event_Girdi!$D$2:$D>=B10);5;TRUE;3;TRUE;1;TRUE);1;1);"")) | H10: =IF(B10="";"";IFERROR(INDEX(SORT(FILTER(Event_Girdi!$A$2:$F;Event_Girdi!$G$2:$G="Evet";Event_Girdi!$F$2:$F="Evet";Event_Girdi!$C$2:$C<=B10;Event_Girdi!$D$2:$D>=B10);3;TRUE;1;TRUE);1;1);G10)) | I10: =IF(B10="";"";IFERROR(TEXTJOIN(" > ";TRUE;INDEX(SORT(FILTER(Event_Girdi!$A$2:$H;Event_Girdi!$G$2:$G="Evet";Event_Girdi!$C$2:$C<=B10;Event_Girdi!$D$2:$D>=B10);8;TRUE;5;TRUE;3;TRUE;1;TRUE);;1));"")) | J10: =IF(B10="";"";IF(F10>1;"Cakisiyor";"Normal"))
A11: =IF(B11="";"";"W"&(ROW()-1)) | B11: =IF(B10="";"";IF(B10+7<=MAX(FILTER(Event_Girdi!$D$2:$D;Event_Girdi!$G$2:$G="Evet"))+6;B10+7;"")) | C11: =IF(B11="";"";B11+6) | D11: =IF(B11="";"";TEXT(B11;"dd mmm")&" - "&TEXT(C11;"dd mmm")) | E11: =IF(B11="";"";IFERROR(TEXTJOIN("; ";TRUE;FILTER(Event_Girdi!$A$2:$A;Event_Girdi!$G$2:$G="Evet";Event_Girdi!$C$2:$C<=C11;Event_Girdi!$D$2:$D>=B11));"")) | F11: =IF(B11="";"";MAX(COUNTIFS(Event_Girdi!$C$2:$C;"<="&B11;Event_Girdi!$D$2:$D;">="&B11;Event_Girdi!$G$2:$G;"Evet");COUNTIFS(Event_Girdi!$C$2:$C;"<="&B11+1;Event_Girdi!$D$2:$D;">="&B11+1;Event_Girdi!$G$2:$G;"Evet");COUNTIFS(Event_Girdi!$C$2:$C;"<="&B11+2;Event_Girdi!$D$2:$D;">="&B11+2;Event_Girdi!$G$2:$G;"Evet");COUNTIFS(Event_Girdi!$C$2:$C;"<="&B11+3;Event_Girdi!$D$2:$D;">="&B11+3;Event_Girdi!$G$2:$G;"Evet");COUNTIFS(Event_Girdi!$C$2:$C;"<="&B11+4;Event_Girdi!$D$2:$D;">="&B11+4;Event_Girdi!$G$2:$G;"Evet");COUNTIFS(Event_Girdi!$C$2:$C;"<="&B11+5;Event_Girdi!$D$2:$D;">="&B11+5;Event_Girdi!$G$2:$G;"Evet");COUNTIFS(Event_Girdi!$C$2:$C;"<="&B11+6;Event_Girdi!$D$2:$D;">="&B11+6;Event_Girdi!$G$2:$G;"Evet"))) | G11: =IF(B11="";"";IFERROR(INDEX(SORT(FILTER(Event_Girdi!$A$2:$E;Event_Girdi!$G$2:$G="Evet";Event_Girdi!$C$2:$C<=B11;Event_Girdi!$D$2:$D>=B11);5;TRUE;3;TRUE;1;TRUE);1;1);"")) | H11: =IF(B11="";"";IFERROR(INDEX(SORT(FILTER(Event_Girdi!$A$2:$F;Event_Girdi!$G$2:$G="Evet";Event_Girdi!$F$2:$F="Evet";Event_Girdi!$C$2:$C<=B11;Event_Girdi!$D$2:$D>=B11);3;TRUE;1;TRUE);1;1);G11)) | I11: =IF(B11="";"";IFERROR(TEXTJOIN(" > ";TRUE;INDEX(SORT(FILTER(Event_Girdi!$A$2:$H;Event_Girdi!$G$2:$G="Evet";Event_Girdi!$C$2:$C<=B11;Event_Girdi!$D$2:$D>=B11);8;TRUE;5;TRUE;3;TRUE;1;TRUE);;1));"")) | J11: =IF(B11="";"";IF(F11>1;"Cakisiyor";"Normal"))
A12: =IF(B12="";"";"W"&(ROW()-1)) | B12: =IF(B11="";"";IF(B11+7<=MAX(FILTER(Event_Girdi!$D$2:$D;Event_Girdi!$G$2:$G="Evet"))+6;B11+7;"")) | C12: =IF(B12="";"";B12+6) | D12: =IF(B12="";"";TEXT(B12;"dd mmm")&" - "&TEXT(C12;"dd mmm")) | E12: =IF(B12="";"";IFERROR(TEXTJOIN("; ";TRUE;FILTER(Event_Girdi!$A$2:$A;Event_Girdi!$G$2:$G="Evet";Event_Girdi!$C$2:$C<=C12;Event_Girdi!$D$2:$D>=B12));"")) | F12: =IF(B12="";"";MAX(COUNTIFS(Event_Girdi!$C$2:$C;"<="&B12;Event_Girdi!$D$2:$D;">="&B12;Event_Girdi!$G$2:$G;"Evet");COUNTIFS(Event_Girdi!$C$2:$C;"<="&B12+1;Event_Girdi!$D$2:$D;">="&B12+1;Event_Girdi!$G$2:$G;"Evet");COUNTIFS(Event_Girdi!$C$2:$C;"<="&B12+2;Event_Girdi!$D$2:$D;">="&B12+2;Event_Girdi!$G$2:$G;"Evet");COUNTIFS(Event_Girdi!$C$2:$C;"<="&B12+3;Event_Girdi!$D$2:$D;">="&B12+3;Event_Girdi!$G$2:$G;"Evet");COUNTIFS(Event_Girdi!$C$2:$C;"<="&B12+4;Event_Girdi!$D$2:$D;">="&B12+4;Event_Girdi!$G$2:$G;"Evet");COUNTIFS(Event_Girdi!$C$2:$C;"<="&B12+5;Event_Girdi!$D$2:$D;">="&B12+5;Event_Girdi!$G$2:$G;"Evet");COUNTIFS(Event_Girdi!$C$2:$C;"<="&B12+6;Event_Girdi!$D$2:$D;">="&B12+6;Event_Girdi!$G$2:$G;"Evet"))) | G12: =IF(B12="";"";IFERROR(INDEX(SORT(FILTER(Event_Girdi!$A$2:$E;Event_Girdi!$G$2:$G="Evet";Event_Girdi!$C$2:$C<=B12;Event_Girdi!$D$2:$D>=B12);5;TRUE;3;TRUE;1;TRUE);1;1);"")) | H12: =IF(B12="";"";IFERROR(INDEX(SORT(FILTER(Event_Girdi!$A$2:$F;Event_Girdi!$G$2:$G="Evet";Event_Girdi!$F$2:$F="Evet";Event_Girdi!$C$2:$C<=B12;Event_Girdi!$D$2:$D>=B12);3;TRUE;1;TRUE);1;1);G12)) | I12: =IF(B12="";"";IFERROR(TEXTJOIN(" > ";TRUE;INDEX(SORT(FILTER(Event_Girdi!$A$2:$H;Event_Girdi!$G$2:$G="Evet";Event_Girdi!$C$2:$C<=B12;Event_Girdi!$D$2:$D>=B12);8;TRUE;5;TRUE;3;TRUE;1;TRUE);;1));"")) | J12: =IF(B12="";"";IF(F12>1;"Cakisiyor";"Normal"))
A13: =IF(B13="";"";"W"&(ROW()-1)) | B13: =IF(B12="";"";IF(B12+7<=MAX(FILTER(Event_Girdi!$D$2:$D;Event_Girdi!$G$2:$G="Evet"))+6;B12+7;"")) | C13: =IF(B13="";"";B13+6) | D13: =IF(B13="";"";TEXT(B13;"dd mmm")&" - "&TEXT(C13;"dd mmm")) | E13: =IF(B13="";"";IFERROR(TEXTJOIN("; ";TRUE;FILTER(Event_Girdi!$A$2:$A;Event_Girdi!$G$2:$G="Evet";Event_Girdi!$C$2:$C<=C13;Event_Girdi!$D$2:$D>=B13));"")) | F13: =IF(B13="";"";MAX(COUNTIFS(Event_Girdi!$C$2:$C;"<="&B13;Event_Girdi!$D$2:$D;">="&B13;Event_Girdi!$G$2:$G;"Evet");COUNTIFS(Event_Girdi!$C$2:$C;"<="&B13+1;Event_Girdi!$D$2:$D;">="&B13+1;Event_Girdi!$G$2:$G;"Evet");COUNTIFS(Event_Girdi!$C$2:$C;"<="&B13+2;Event_Girdi!$D$2:$D;">="&B13+2;Event_Girdi!$G$2:$G;"Evet");COUNTIFS(Event_Girdi!$C$2:$C;"<="&B13+3;Event_Girdi!$D$2:$D;">="&B13+3;Event_Girdi!$G$2:$G;"Evet");COUNTIFS(Event_Girdi!$C$2:$C;"<="&B13+4;Event_Girdi!$D$2:$D;">="&B13+4;Event_Girdi!$G$2:$G;"Evet");COUNTIFS(Event_Girdi!$C$2:$C;"<="&B13+5;Event_Girdi!$D$2:$D;">="&B13+5;Event_Girdi!$G$2:$G;"Evet");COUNTIFS(Event_Girdi!$C$2:$C;"<="&B13+6;Event_Girdi!$D$2:$D;">="&B13+6;Event_Girdi!$G$2:$G;"Evet"))) | G13: =IF(B13="";"";IFERROR(INDEX(SORT(FILTER(Event_Girdi!$A$2:$E;Event_Girdi!$G$2:$G="Evet";Event_Girdi!$C$2:$C<=B13;Event_Girdi!$D$2:$D>=B13);5;TRUE;3;TRUE;1;TRUE);1;1);"")) | H13: =IF(B13="";"";IFERROR(INDEX(SORT(FILTER(Event_Girdi!$A$2:$F;Event_Girdi!$G$2:$G="Evet";Event_Girdi!$F$2:$F="Evet";Event_Girdi!$C$2:$C<=B13;Event_Girdi!$D$2:$D>=B13);3;TRUE;1;TRUE);1;1);G13)) | I13: =IF(B13="";"";IFERROR(TEXTJOIN(" > ";TRUE;INDEX(SORT(FILTER(Event_Girdi!$A$2:$H;Event_Girdi!$G$2:$G="Evet";Event_Girdi!$C$2:$C<=B13;Event_Girdi!$D$2:$D>=B13);8;TRUE;5;TRUE;3;TRUE;1;TRUE);;1));"")) | J13: =IF(B13="";"";IF(F13>1;"Cakisiyor";"Normal"))
A14: =IF(B14="";"";"W"&(ROW()-1)) | B14: =IF(B13="";"";IF(B13+7<=MAX(FILTER(Event_Girdi!$D$2:$D;Event_Girdi!$G$2:$G="Evet"))+6;B13+7;"")) | C14: =IF(B14="";"";B14+6) | D14: =IF(B14="";"";TEXT(B14;"dd mmm")&" - "&TEXT(C14;"dd mmm")) | E14: =IF(B14="";"";IFERROR(TEXTJOIN("; ";TRUE;FILTER(Event_Girdi!$A$2:$A;Event_Girdi!$G$2:$G="Evet";Event_Girdi!$C$2:$C<=C14;Event_Girdi!$D$2:$D>=B14));"")) | F14: =IF(B14="";"";MAX(COUNTIFS(Event_Girdi!$C$2:$C;"<="&B14;Event_Girdi!$D$2:$D;">="&B14;Event_Girdi!$G$2:$G;"Evet");COUNTIFS(Event_Girdi!$C$2:$C;"<="&B14+1;Event_Girdi!$D$2:$D;">="&B14+1;Event_Girdi!$G$2:$G;"Evet");COUNTIFS(Event_Girdi!$C$2:$C;"<="&B14+2;Event_Girdi!$D$2:$D;">="&B14+2;Event_Girdi!$G$2:$G;"Evet");COUNTIFS(Event_Girdi!$C$2:$C;"<="&B14+3;Event_Girdi!$D$2:$D;">="&B14+3;Event_Girdi!$G$2:$G;"Evet");COUNTIFS(Event_Girdi!$C$2:$C;"<="&B14+4;Event_Girdi!$D$2:$D;">="&B14+4;Event_Girdi!$G$2:$G;"Evet");COUNTIFS(Event_Girdi!$C$2:$C;"<="&B14+5;Event_Girdi!$D$2:$D;">="&B14+5;Event_Girdi!$G$2:$G;"Evet");COUNTIFS(Event_Girdi!$C$2:$C;"<="&B14+6;Event_Girdi!$D$2:$D;">="&B14+6;Event_Girdi!$G$2:$G;"Evet"))) | G14: =IF(B14="";"";IFERROR(INDEX(SORT(FILTER(Event_Girdi!$A$2:$E;Event_Girdi!$G$2:$G="Evet";Event_Girdi!$C$2:$C<=B14;Event_Girdi!$D$2:$D>=B14);5;TRUE;3;TRUE;1;TRUE);1;1);"")) | H14: =IF(B14="";"";IFERROR(INDEX(SORT(FILTER(Event_Girdi!$A$2:$F;Event_Girdi!$G$2:$G="Evet";Event_Girdi!$F$2:$F="Evet";Event_Girdi!$C$2:$C<=B14;Event_Girdi!$D$2:$D>=B14);3;TRUE;1;TRUE);1;1);G14)) | I14: =IF(B14="";"";IFERROR(TEXTJOIN(" > ";TRUE;INDEX(SORT(FILTER(Event_Girdi!$A$2:$H;Event_Girdi!$G$2:$G="Evet";Event_Girdi!$C$2:$C<=B14;Event_Girdi!$D$2:$D>=B14);8;TRUE;5;TRUE;3;TRUE;1;TRUE);;1));"")) | J14: =IF(B14="";"";IF(F14>1;"Cakisiyor";"Normal"))
... A31: =IF(B31="";"";"W"&(ROW()-1)) | B31: =IF(B30="";"";IF(B30+7<=MAX(FILTER(Event_Girdi!$D$2:$D;Event_Girdi!$G$2:$G="Evet"))+6;B30+7;"")) | C31: =IF(B31="";"";B31+6) | D31: =IF(B31="";"";TEXT(B31;"dd mmm")&" - "&TEXT(C31;"dd mmm")) | E31: =IF(B31="";"";IFERROR(TEXTJOIN("; ";TRUE;FILTER(Event_Girdi!$A$2:$A;Event_Girdi!$G$2:$G="Evet";Event_Girdi!$C$2:$C<=C31;Event_Girdi!$D$2:$D>=B31));"")) | F31: =IF(B31="";"";MAX(COUNTIFS(Event_Girdi!$C$2:$C;"<="&B31;Event_Girdi!$D$2:$D;">="&B31;Event_Girdi!$G$2:$G;"Evet");COUNTIFS(Event_Girdi!$C$2:$C;"<="&B31+1;Event_Girdi!$D$2:$D;">="&B31+1;Event_Girdi!$G$2:$G;"Evet");COUNTIFS(Event_Girdi!$C$2:$C;"<="&B31+2;Event_Girdi!$D$2:$D;">="&B31+2;Event_Girdi!$G$2:$G;"Evet");COUNTIFS(Event_Girdi!$C$2:$C;"<="&B31+3;Event_Girdi!$D$2:$D;">="&B31+3;Event_Girdi!$G$2:$G;"Evet");COUNTIFS(Event_Girdi!$C$2:$C;"<="&B31+4;Event_Girdi!$D$2:$D;">="&B31+4;Event_Girdi!$G$2:$G;"Evet");COUNTIFS(Event_Girdi!$C$2:$C;"<="&B31+5;Event_Girdi!$D$2:$D;">="&B31+5;Event_Girdi!$G$2:$G;"Evet");COUNTIFS(Event_Girdi!$C$2:$C;"<="&B31+6;Event_Girdi!$D$2:$D;">="&B31+6;Event_Girdi!$G$2:$G;"Evet"))) | G31: =IF(B31="";"";IFERROR(INDEX(SORT(FILTER(Event_Girdi!$A$2:$E;Event_Girdi!$G$2:$G="Evet";Event_Girdi!$C$2:$C<=B31;Event_Girdi!$D$2:$D>=B31);5;TRUE;3;TRUE;1;TRUE);1;1);"")) | H31: =IF(B31="";"";IFERROR(INDEX(SORT(FILTER(Event_Girdi!$A$2:$F;Event_Girdi!$G$2:$G="Evet";Event_Girdi!$F$2:$F="Evet";Event_Girdi!$C$2:$C<=B31;Event_Girdi!$D$2:$D>=B31);3;TRUE;1;TRUE);1;1);G31)) | I31: =IF(B31="";"";IFERROR(TEXTJOIN(" > ";TRUE;INDEX(SORT(FILTER(Event_Girdi!$A$2:$H;Event_Girdi!$G$2:$G="Evet";Event_Girdi!$C$2:$C<=B31;Event_Girdi!$D$2:$D>=B31);8;TRUE;5;TRUE;3;TRUE;1;TRUE);;1));"")) | J31: =IF(B31="";"";IF(F31>1;"Cakisiyor";"Normal"))

Sheet Dashboard
A1: DENEME EVENT - Haftalik Dashboard
A3: Toplam Event | B3: =COUNTA(FILTER(Event_Girdi!$A$2:$A;Event_Girdi!$G$2:$G="Evet"))
A4: Toplam Hafta | B4: =COUNTA(FILTER(Hafta_Ozet!$A$2:$A;Hafta_Ozet!$A$2:$A<>""))
A5: Peak Cakisma | B5: =IFERROR(MAX(FILTER(Hafta_Ozet!$F$2:$F;Hafta_Ozet!$F$2:$F<>""));0)
A6: Cakisan Hafta | B6: =COUNTIF(Hafta_Ozet!$F$2:$F;">1")
A8: Hafta | B8: Tarih_Araligi | C8: Aktif_Eventler | D8: Cakisma_Max | E8: Winner_Organik | F8: Winner_Deeplink | G8: Queue | H8: Durum
A9: =IF(Hafta_Ozet!A2="";"";Hafta_Ozet!A2) | B9: =IF(A9="";"";Hafta_Ozet!D2) | C9: =IF(A9="";"";Hafta_Ozet!E2) | D9: =IF(A9="";"";Hafta_Ozet!F2) | E9: =IF(A9="";"";Hafta_Ozet!G2) | F9: =IF(A9="";"";Hafta_Ozet!H2) | G9: =IF(A9="";"";Hafta_Ozet!I2) | H9: =IF(A9="";"";Hafta_Ozet!J2)
A10: =IF(Hafta_Ozet!A3="";"";Hafta_Ozet!A3) | B10: =IF(A10="";"";Hafta_Ozet!D3) | C10: =IF(A10="";"";Hafta_Ozet!E3) | D10: =IF(A10="";"";Hafta_Ozet!F3) | E10: =IF(A10="";"";Hafta_Ozet!G3) | F10: =IF(A10="";"";Hafta_Ozet!H3) | G10: =IF(A10="";"";Hafta_Ozet!I3) | H10: =IF(A10="";"";Hafta_Ozet!J3)
A11: =IF(Hafta_Ozet!A4="";"";Hafta_Ozet!A4) | B11: =IF(A11="";"";Hafta_Ozet!D4) | C11: =IF(A11="";"";Hafta_Ozet!E4) | D11: =IF(A11="";"";Hafta_Ozet!F4) | E11: =IF(A11="";"";Hafta_Ozet!G4) | F11: =IF(A11="";"";Hafta_Ozet!H4) | G11: =IF(A11="";"";Hafta_Ozet!I4) | H11: =IF(A11="";"";Hafta_Ozet!J4)
A12: =IF(Hafta_Ozet!A5="";"";Hafta_Ozet!A5) | B12: =IF(A12="";"";Hafta_Ozet!D5) | C12: =IF(A12="";"";Hafta_Ozet!E5) | D12: =IF(A12="";"";Hafta_Ozet!F5) | E12: =IF(A12="";"";Hafta_Ozet!G5) | F12: =IF(A12="";"";Hafta_Ozet!H5) | G12: =IF(A12="";"";Hafta_Ozet!I5) | H12: =IF(A12="";"";Hafta_Ozet!J5)
A13: =IF(Hafta_Ozet!A6="";"";Hafta_Ozet!A6) | B13: =IF(A13="";"";Hafta_Ozet!D6) | C13: =IF(A13="";"";Hafta_Ozet!E6) | D13: =IF(A13="";"";Hafta_Ozet!F6) | E13: =IF(A13="";"";Hafta_Ozet!G6) | F13: =IF(A13="";"";Hafta_Ozet!H6) | G13: =IF(A13="";"";Hafta_Ozet!I6) | H13: =IF(A13="";"";Hafta_Ozet!J6)
A14: =IF(Hafta_Ozet!A7="";"";Hafta_Ozet!A7) | B14: =IF(A14="";"";Hafta_Ozet!D7) | C14: =IF(A14="";"";Hafta_Ozet!E7) | D14: =IF(A14="";"";Hafta_Ozet!F7) | E14: =IF(A14="";"";Hafta_Ozet!G7) | F14: =IF(A14="";"";Hafta_Ozet!H7) | G14: =IF(A14="";"";Hafta_Ozet!I7) | H14: =IF(A14="";"";Hafta_Ozet!J7)
A15: =IF(Hafta_Ozet!A8="";"";Hafta_Ozet!A8) | B15: =IF(A15="";"";Hafta_Ozet!D8) | C15: =IF(A15="";"";Hafta_Ozet!E8) | D15: =IF(A15="";"";Hafta_Ozet!F8) | E15: =IF(A15="";"";Hafta_Ozet!G8) | F15: =IF(A15="";"";Hafta_Ozet!H8) | G15: =IF(A15="";"";Hafta_Ozet!I8) | H15: =IF(A15="";"";Hafta_Ozet!J8)
A16: =IF(Hafta_Ozet!A9="";"";Hafta_Ozet!A9) | B16: =IF(A16="";"";Hafta_Ozet!D9) | C16: =IF(A16="";"";Hafta_Ozet!E9) | D16: =IF(A16="";"";Hafta_Ozet!F9) | E16: =IF(A16="";"";Hafta_Ozet!G9) | F16: =IF(A16="";"";Hafta_Ozet!H9) | G16: =IF(A16="";"";Hafta_Ozet!I9) | H16: =IF(A16="";"";Hafta_Ozet!J9)
A17: =IF(Hafta_Ozet!A10="";"";Hafta_Ozet!A10) | B17: =IF(A17="";"";Hafta_Ozet!D10) | C17: =IF(A17="";"";Hafta_Ozet!E10) | D17: =IF(A17="";"";Hafta_Ozet!F10) | E17: =IF(A17="";"";Hafta_Ozet!G10) | F17: =IF(A17="";"";Hafta_Ozet!H10) | G17: =IF(A17="";"";Hafta_Ozet!I10) | H17: =IF(A17="";"";Hafta_Ozet!J10)
A18: =IF(Hafta_Ozet!A11="";"";Hafta_Ozet!A11) | B18: =IF(A18="";"";Hafta_Ozet!D11) | C18: =IF(A18="";"";Hafta_Ozet!E11) | D18: =IF(A18="";"";Hafta_Ozet!F11) | E18: =IF(A18="";"";Hafta_Ozet!G11) | F18: =IF(A18="";"";Hafta_Ozet!H11) | G18: =IF(A18="";"";Hafta_Ozet!I11) | H18: =IF(A18="";"";Hafta_Ozet!J11)
A19: =IF(Hafta_Ozet!A12="";"";Hafta_Ozet!A12) | B19: =IF(A19="";"";Hafta_Ozet!D12) | C19: =IF(A19="";"";Hafta_Ozet!E12) | D19: =IF(A19="";"";Hafta_Ozet!F12) | E19: =IF(A19="";"";Hafta_Ozet!G12) | F19: =IF(A19="";"";Hafta_Ozet!H12) | G19: =IF(A19="";"";Hafta_Ozet!I12) | H19: =IF(A19="";"";Hafta_Ozet!J12)
A20: =IF(Hafta_Ozet!A13="";"";Hafta_Ozet!A13) | B20: =IF(A20="";"";Hafta_Ozet!D13) | C20: =IF(A20="";"";Hafta_Ozet!E13) | D20: =IF(A20="";"";Hafta_Ozet!F13) | E20: =IF(A20="";"";Hafta_Ozet!G13) | F20: =IF(A20="";"";Hafta_Ozet!H13) | G20: =IF(A20="";"";Hafta_Ozet!I13) | H20: =IF(A20="";"";Hafta_Ozet!J13)
... A28: =IF(Hafta_Ozet!A21="";"";Hafta_Ozet!A21) | B28: =IF(A28="";"";Hafta_Ozet!D21) | C28: =IF(A28="";"";Hafta_Ozet!E21) | D28: =IF(A28="";"";Hafta_Ozet!F21) | E28: =IF(A28="";"";Hafta_Ozet!G21) | F28: =IF(A28="";"";Hafta_Ozet!H21) | G28: =IF(A28="";"";Hafta_Ozet!I21) | H28: =IF(A28="";"";Hafta_Ozet!J21)
A31: Event_ID | B31: Event_Adi | C31: Priority | D31: =IF(Hafta_Ozet!A2="";"";Hafta_Ozet!A2&" "&Hafta_Ozet!D2) | E31: =IF(Hafta_Ozet!A3="";"";Hafta_Ozet!A3&" "&Hafta_Ozet!D3) | F31: =IF(Hafta_Ozet!A4="";"";Hafta_Ozet!A4&" "&Hafta_Ozet!D4) | G31: =IF(Hafta_Ozet!A5="";"";Hafta_Ozet!A5&" "&Hafta_Ozet!D5) | H31: =IF(Hafta_Ozet!A6="";"";Hafta_Ozet!A6&" "&Hafta_Ozet!D6) | I31: =IF(Hafta_Ozet!A7="";"";Hafta_Ozet!A7&" "&Hafta_Ozet!D7) | J31: =IF(Hafta_Ozet!A8="";"";Hafta_Ozet!A8&" "&Hafta_Ozet!D8) | K31: =IF(Hafta_Ozet!A9="";"";Hafta_Ozet!A9&" "&Hafta_Ozet!D9) | L31: =IF(Hafta_Ozet!A10="";"";Hafta_Ozet!A10&" "&Hafta_Ozet!D10) | M31: =IF(Hafta_Ozet!A11="";"";Hafta_Ozet!A11&" "&Hafta_Ozet!D11) | N31: =IF(Hafta_Ozet!A12="";"";Hafta_Ozet!A12&" "&Hafta_Ozet!D12) | O31: =IF(Hafta_Ozet!A13="";"";Hafta_Ozet!A13&" "&Hafta_Ozet!D13) | P31: =IF(Hafta_Ozet!A14="";"";Hafta_Ozet!A14&" "&Hafta_Ozet!D14) | Q31: =IF(Hafta_Ozet!A15="";"";Hafta_Ozet!A15&" "&Hafta_Ozet!D15) | R31: =IF(Hafta_Ozet!A16="";"";Hafta_Ozet!A16&" "&Hafta_Ozet!D16) | S31: =IF(Hafta_Ozet!A17="";"";Hafta_Ozet!A17&" "&Hafta_Ozet!D17) | T31: =IF(Hafta_Ozet!A18="";"";Hafta_Ozet!A18&" "&Hafta_Ozet!D18) | U31: =IF(Hafta_Ozet!A19="";"";Hafta_Ozet!A19&" "&Hafta_Ozet!D19) | V31: =IF(Hafta_Ozet!A20="";"";Hafta_Ozet!A20&" "&Hafta_Ozet!D20) | W31: =IF(Hafta_Ozet!A21="";"";Hafta_Ozet!A21&" "&Hafta_Ozet!D21)
A32: =IFERROR(INDEX(FILTER(Event_Girdi!$A$2:$A;Event_Girdi!$G$2:$G="Evet");1);"") | B32: =IF($A32="";"";INDEX(Event_Girdi!$B:$B;MATCH($A32;Event_Girdi!$A:$A;0))) | C32: =IF($A32="";"";INDEX(Event_Girdi!$E:$E;MATCH($A32;Event_Girdi!$A:$A;0))) | D32: =IF($A32="";"";IF(Hafta_Ozet!$B2="";"";IF(AND(INDEX(Event_Girdi!$C:$C;MATCH($A32;Event_Girdi!$A:$A;0))<=Hafta_Ozet!$C2;INDEX(Event_Girdi!$D:$D;MATCH($A32;Event_Girdi!$A:$A;0))>=Hafta_Ozet!$B2);"ACTIVE";""))) | E32: =IF($A32="";"";IF(Hafta_Ozet!$B3="";"";IF(AND(INDEX(Event_Girdi!$C:$C;MATCH($A32;Event_Girdi!$A:$A;0))<=Hafta_Ozet!$C3;INDEX(Event_Girdi!$D:$D;MATCH($A32;Event_Girdi!$A:$A;0))>=Hafta_Ozet!$B3);"ACTIVE";""))) | F32: =IF($A32="";"";IF(Hafta_Ozet!$B4="";"";IF(AND(INDEX(Event_Girdi!$C:$C;MATCH($A32;Event_Girdi!$A:$A;0))<=Hafta_Ozet!$C4;INDEX(Event_Girdi!$D:$D;MATCH($A32;Event_Girdi!$A:$A;0))>=Hafta_Ozet!$B4);"ACTIVE";""))) | G32: =IF($A32="";"";IF(Hafta_Ozet!$B5="";"";IF(AND(INDEX(Event_Girdi!$C:$C;MATCH($A32;Event_Girdi!$A:$A;0))<=Hafta_Ozet!$C5;INDEX(Event_Girdi!$D:$D;MATCH($A32;Event_Girdi!$A:$A;0))>=Hafta_Ozet!$B5);"ACTIVE";""))) | H32: =IF($A32="";"";IF(Hafta_Ozet!$B6="";"";IF(AND(INDEX(Event_Girdi!$C:$C;MATCH($A32;Event_Girdi!$A:$A;0))<=Hafta_Ozet!$C6;INDEX(Event_Girdi!$D:$D;MATCH($A32;Event_Girdi!$A:$A;0))>=Hafta_Ozet!$B6);"ACTIVE";""))) | I32: =IF($A32="";"";IF(Hafta_Ozet!$B7="";"";IF(AND(INDEX(Event_Girdi!$C:$C;MATCH($A32;Event_Girdi!$A:$A;0))<=Hafta_Ozet!$C7;INDEX(Event_Girdi!$D:$D;MATCH($A32;Event_Girdi!$A:$A;0))>=Hafta_Ozet!$B7);"ACTIVE";""))) | J32: =IF($A32="";"";IF(Hafta_Ozet!$B8="";"";IF(AND(INDEX(Event_Girdi!$C:$C;MATCH($A32;Event_Girdi!$A:$A;0))<=Hafta_Ozet!$C8;INDEX(Event_Girdi!$D:$D;MATCH($A32;Event_Girdi!$A:$A;0))>=Hafta_Ozet!$B8);"ACTIVE";""))) | K32: =IF($A32="";"";IF(Hafta_Ozet!$B9="";"";IF(AND(INDEX(Event_Girdi!$C:$C;MATCH($A32;Event_Girdi!$A:$A;0))<=Hafta_Ozet!$C9;INDEX(Event_Girdi!$D:$D;MATCH($A32;Event_Girdi!$A:$A;0))>=Hafta_Ozet!$B9);"ACTIVE";""))) | L32: =IF($A32="";"";IF(Hafta_Ozet!$B10="";"";IF(AND(INDEX(Event_Girdi!$C:$C;MATCH($A32;Event_Girdi!$A:$A;0))<=Hafta_Ozet!$C10;INDEX(Event_Girdi!$D:$D;MATCH($A32;Event_Girdi!$A:$A;0))>=Hafta_Ozet!$B10);"ACTIVE";""))) | M32: =IF($A32="";"";IF(Hafta_Ozet!$B11="";"";IF(AND(INDEX(Event_Girdi!$C:$C;MATCH($A32;Event_Girdi!$A:$A;0))<=Hafta_Ozet!$C11;INDEX(Event_Girdi!$D:$D;MATCH($A32;Event_Girdi!$A:$A;0))>=Hafta_Ozet!$B11);"ACTIVE";""))) | N32: =IF($A32="";"";IF(Hafta_Ozet!$B12="";"";IF(AND(INDEX(Event_Girdi!$C:$C;MATCH($A32;Event_Girdi!$A:$A;0))<=Hafta_Ozet!$C12;INDEX(Event_Girdi!$D:$D;MATCH($A32;Event_Girdi!$A:$A;0))>=Hafta_Ozet!$B12);"ACTIVE";""))) | O32: =IF($A32="";"";IF(Hafta_Ozet!$B13="";"";IF(AND(INDEX(Event_Girdi!$C:$C;MATCH($A32;Event_Girdi!$A:$A;0))<=Hafta_Ozet!$C13;INDEX(Event_Girdi!$D:$D;MATCH($A32;Event_Girdi!$A:$A;0))>=Hafta_Ozet!$B13);"ACTIVE";""))) | P32: =IF($A32="";"";IF(Hafta_Ozet!$B14="";"";IF(AND(INDEX(Event_Girdi!$C:$C;MATCH($A32;Event_Girdi!$A:$A;0))<=Hafta_Ozet!$C14;INDEX(Event_Girdi!$D:$D;MATCH($A32;Event_Girdi!$A:$A;0))>=Hafta_Ozet!$B14);"ACTIVE";""))) | Q32: =IF($A32="";"";IF(Hafta_Ozet!$B15="";"";IF(AND(INDEX(Event_Girdi!$C:$C;MATCH($A32;Event_Girdi!$A:$A;0))<=Hafta_Ozet!$C15;INDEX(Event_Girdi!$D:$D;MATCH($A32;Event_Girdi!$A:$A;0))>=Hafta_Ozet!$B15);"ACTIVE";""))) | R32: =IF($A32="";"";IF(Hafta_Ozet!$B16="";"";IF(AND(INDEX(Event_Girdi!$C:$C;MATCH($A32;Event_Girdi!$A:$A;0))<=Hafta_Ozet!$C16;INDEX(Event_Girdi!$D:$D;MATCH($A32;Event_Girdi!$A:$A;0))>=Hafta_Ozet!$B16);"ACTIVE";""))) | S32: =IF($A32="";"";IF(Hafta_Ozet!$B17="";"";IF(AND(INDEX(Event_Girdi!$C:$C;MATCH($A32;Event_Girdi!$A:$A;0))<=Hafta_Ozet!$C17;INDEX(Event_Girdi!$D:$D;MATCH($A32;Event_Girdi!$A:$A;0))>=Hafta_Ozet!$B17);"ACTIVE";""))) | T32: =IF($A32="";"";IF(Hafta_Ozet!$B18="";"";IF(AND(INDEX(Event_Girdi!$C:$C;MATCH($A32;Event_Girdi!$A:$A;0))<=Hafta_Ozet!$C18;INDEX(Event_Girdi!$D:$D;MATCH($A32;Event_Girdi!$A:$A;0))>=Hafta_Ozet!$B18);"ACTIVE";""))) | U32: =IF($A32="";"";IF(Hafta_Ozet!$B19="";"";IF(AND(INDEX(Event_Girdi!$C:$C;MATCH($A32;Event_Girdi!$A:$A;0))<=Hafta_Ozet!$C19;INDEX(Event_Girdi!$D:$D;MATCH($A32;Event_Girdi!$A:$A;0))>=Hafta_Ozet!$B19);"ACTIVE";""))) | V32: =IF($A32="";"";IF(Hafta_Ozet!$B20="";"";IF(AND(INDEX(Event_Girdi!$C:$C;MATCH($A32;Event_Girdi!$A:$A;0))<=Hafta_Ozet!$C20;INDEX(Event_Girdi!$D:$D;MATCH($A32;Event_Girdi!$A:$A;0))>=Hafta_Ozet!$B20);"ACTIVE";""))) | W32: =IF($A32="";"";IF(Hafta_Ozet!$B21="";"";IF(AND(INDEX(Event_Girdi!$C:$C;MATCH($A32;Event_Girdi!$A:$A;0))<=Hafta_Ozet!$C21;INDEX(Event_Girdi!$D:$D;MATCH($A32;Event_Girdi!$A:$A;0))>=Hafta_Ozet!$B21);"ACTIVE";"")))
A33: =IFERROR(INDEX(FILTER(Event_Girdi!$A$2:$A;Event_Girdi!$G$2:$G="Evet");2);"") | B33: =IF($A33="";"";INDEX(Event_Girdi!$B:$B;MATCH($A33;Event_Girdi!$A:$A;0))) | C33: =IF($A33="";"";INDEX(Event_Girdi!$E:$E;MATCH($A33;Event_Girdi!$A:$A;0))) | D33: =IF($A33="";"";IF(Hafta_Ozet!$B2="";"";IF(AND(INDEX(Event_Girdi!$C:$C;MATCH($A33;Event_Girdi!$A:$A;0))<=Hafta_Ozet!$C2;INDEX(Event_Girdi!$D:$D;MATCH($A33;Event_Girdi!$A:$A;0))>=Hafta_Ozet!$B2);"ACTIVE";""))) | E33: =IF($A33="";"";IF(Hafta_Ozet!$B3="";"";IF(AND(INDEX(Event_Girdi!$C:$C;MATCH($A33;Event_Girdi!$A:$A;0))<=Hafta_Ozet!$C3;INDEX(Event_Girdi!$D:$D;MATCH($A33;Event_Girdi!$A:$A;0))>=Hafta_Ozet!$B3);"ACTIVE";""))) | F33: =IF($A33="";"";IF(Hafta_Ozet!$B4="";"";IF(AND(INDEX(Event_Girdi!$C:$C;MATCH($A33;Event_Girdi!$A:$A;0))<=Hafta_Ozet!$C4;INDEX(Event_Girdi!$D:$D;MATCH($A33;Event_Girdi!$A:$A;0))>=Hafta_Ozet!$B4);"ACTIVE";""))) | G33: =IF($A33="";"";IF(Hafta_Ozet!$B5="";"";IF(AND(INDEX(Event_Girdi!$C:$C;MATCH($A33;Event_Girdi!$A:$A;0))<=Hafta_Ozet!$C5;INDEX(Event_Girdi!$D:$D;MATCH($A33;Event_Girdi!$A:$A;0))>=Hafta_Ozet!$B5);"ACTIVE";""))) | H33: =IF($A33="";"";IF(Hafta_Ozet!$B6="";"";IF(AND(INDEX(Event_Girdi!$C:$C;MATCH($A33;Event_Girdi!$A:$A;0))<=Hafta_Ozet!$C6;INDEX(Event_Girdi!$D:$D;MATCH($A33;Event_Girdi!$A:$A;0))>=Hafta_Ozet!$B6);"ACTIVE";""))) | I33: =IF($A33="";"";IF(Hafta_Ozet!$B7="";"";IF(AND(INDEX(Event_Girdi!$C:$C;MATCH($A33;Event_Girdi!$A:$A;0))<=Hafta_Ozet!$C7;INDEX(Event_Girdi!$D:$D;MATCH($A33;Event_Girdi!$A:$A;0))>=Hafta_Ozet!$B7);"ACTIVE";""))) | J33: =IF($A33="";"";IF(Hafta_Ozet!$B8="";"";IF(AND(INDEX(Event_Girdi!$C:$C;MATCH($A33;Event_Girdi!$A:$A;0))<=Hafta_Ozet!$C8;INDEX(Event_Girdi!$D:$D;MATCH($A33;Event_Girdi!$A:$A;0))>=Hafta_Ozet!$B8);"ACTIVE";""))) | K33: =IF($A33="";"";IF(Hafta_Ozet!$B9="";"";IF(AND(INDEX(Event_Girdi!$C:$C;MATCH($A33;Event_Girdi!$A:$A;0))<=Hafta_Ozet!$C9;INDEX(Event_Girdi!$D:$D;MATCH($A33;Event_Girdi!$A:$A;0))>=Hafta_Ozet!$B9);"ACTIVE";""))) | L33: =IF($A33="";"";IF(Hafta_Ozet!$B10="";"";IF(AND(INDEX(Event_Girdi!$C:$C;MATCH($A33;Event_Girdi!$A:$A;0))<=Hafta_Ozet!$C10;INDEX(Event_Girdi!$D:$D;MATCH($A33;Event_Girdi!$A:$A;0))>=Hafta_Ozet!$B10);"ACTIVE";""))) | M33: =IF($A33="";"";IF(Hafta_Ozet!$B11="";"";IF(AND(INDEX(Event_Girdi!$C:$C;MATCH($A33;Event_Girdi!$A:$A;0))<=Hafta_Ozet!$C11;INDEX(Event_Girdi!$D:$D;MATCH($A33;Event_Girdi!$A:$A;0))>=Hafta_Ozet!$B11);"ACTIVE";""))) | N33: =IF($A33="";"";IF(Hafta_Ozet!$B12="";"";IF(AND(INDEX(Event_Girdi!$C:$C;MATCH($A33;Event_Girdi!$A:$A;0))<=Hafta_Ozet!$C12;INDEX(Event_Girdi!$D:$D;MATCH($A33;Event_Girdi!$A:$A;0))>=Hafta_Ozet!$B12);"ACTIVE";""))) | O33: =IF($A33="";"";IF(Hafta_Ozet!$B13="";"";IF(AND(INDEX(Event_Girdi!$C:$C;MATCH($A33;Event_Girdi!$A:$A;0))<=Hafta_Ozet!$C13;INDEX(Event_Girdi!$D:$D;MATCH($A33;Event_Girdi!$A:$A;0))>=Hafta_Ozet!$B13);"ACTIVE";""))) | P33: =IF($A33="";"";IF(Hafta_Ozet!$B14="";"";IF(AND(INDEX(Event_Girdi!$C:$C;MATCH($A33;Event_Girdi!$A:$A;0))<=Hafta_Ozet!$C14;INDEX(Event_Girdi!$D:$D;MATCH($A33;Event_Girdi!$A:$A;0))>=Hafta_Ozet!$B14);"ACTIVE";""))) | Q33: =IF($A33="";"";IF(Hafta_Ozet!$B15="";"";IF(AND(INDEX(Event_Girdi!$C:$C;MATCH($A33;Event_Girdi!$A:$A;0))<=Hafta_Ozet!$C15;INDEX(Event_Girdi!$D:$D;MATCH($A33;Event_Girdi!$A:$A;0))>=Hafta_Ozet!$B15);"ACTIVE";""))) | R33: =IF($A33="";"";IF(Hafta_Ozet!$B16="";"";IF(AND(INDEX(Event_Girdi!$C:$C;MATCH($A33;Event_Girdi!$A:$A;0))<=Hafta_Ozet!$C16;INDEX(Event_Girdi!$D:$D;MATCH($A33;Event_Girdi!$A:$A;0))>=Hafta_Ozet!$B16);"ACTIVE";""))) | S33: =IF($A33="";"";IF(Hafta_Ozet!$B17="";"";IF(AND(INDEX(Event_Girdi!$C:$C;MATCH($A33;Event_Girdi!$A:$A;0))<=Hafta_Ozet!$C17;INDEX(Event_Girdi!$D:$D;MATCH($A33;Event_Girdi!$A:$A;0))>=Hafta_Ozet!$B17);"ACTIVE";""))) | T33: =IF($A33="";"";IF(Hafta_Ozet!$B18="";"";IF(AND(INDEX(Event_Girdi!$C:$C;MATCH($A33;Event_Girdi!$A:$A;0))<=Hafta_Ozet!$C18;INDEX(Event_Girdi!$D:$D;MATCH($A33;Event_Girdi!$A:$A;0))>=Hafta_Ozet!$B18);"ACTIVE";""))) | U33: =IF($A33="";"";IF(Hafta_Ozet!$B19="";"";IF(AND(INDEX(Event_Girdi!$C:$C;MATCH($A33;Event_Girdi!$A:$A;0))<=Hafta_Ozet!$C19;INDEX(Event_Girdi!$D:$D;MATCH($A33;Event_Girdi!$A:$A;0))>=Hafta_Ozet!$B19);"ACTIVE";""))) | V33: =IF($A33="";"";IF(Hafta_Ozet!$B20="";"";IF(AND(INDEX(Event_Girdi!$C:$C;MATCH($A33;Event_Girdi!$A:$A;0))<=Hafta_Ozet!$C20;INDEX(Event_Girdi!$D:$D;MATCH($A33;Event_Girdi!$A:$A;0))>=Hafta_Ozet!$B20);"ACTIVE";""))) | W33: =IF($A33="";"";IF(Hafta_Ozet!$B21="";"";IF(AND(INDEX(Event_Girdi!$C:$C;MATCH($A33;Event_Girdi!$A:$A;0))<=Hafta_Ozet!$C21;INDEX(Event_Girdi!$D:$D;MATCH($A33;Event_Girdi!$A:$A;0))>=Hafta_Ozet!$B21);"ACTIVE";"")))
A34: =IFERROR(INDEX(FILTER(Event_Girdi!$A$2:$A;Event_Girdi!$G$2:$G="Evet");3);"") | B34: =IF($A34="";"";INDEX(Event_Girdi!$B:$B;MATCH($A34;Event_Girdi!$A:$A;0))) | C34: =IF($A34="";"";INDEX(Event_Girdi!$E:$E;MATCH($A34;Event_Girdi!$A:$A;0))) | D34: =IF($A34="";"";IF(Hafta_Ozet!$B2="";"";IF(AND(INDEX(Event_Girdi!$C:$C;MATCH($A34;Event_Girdi!$A:$A;0))<=Hafta_Ozet!$C2;INDEX(Event_Girdi!$D:$D;MATCH($A34;Event_Girdi!$A:$A;0))>=Hafta_Ozet!$B2);"ACTIVE";""))) | E34: =IF($A34="";"";IF(Hafta_Ozet!$B3="";"";IF(AND(INDEX(Event_Girdi!$C:$C;MATCH($A34;Event_Girdi!$A:$A;0))<=Hafta_Ozet!$C3;INDEX(Event_Girdi!$D:$D;MATCH($A34;Event_Girdi!$A:$A;0))>=Hafta_Ozet!$B3);"ACTIVE";""))) | F34: =IF($A34="";"";IF(Hafta_Ozet!$B4="";"";IF(AND(INDEX(Event_Girdi!$C:$C;MATCH($A34;Event_Girdi!$A:$A;0))<=Hafta_Ozet!$C4;INDEX(Event_Girdi!$D:$D;MATCH($A34;Event_Girdi!$A:$A;0))>=Hafta_Ozet!$B4);"ACTIVE";""))) | G34: =IF($A34="";"";IF(Hafta_Ozet!$B5="";"";IF(AND(INDEX(Event_Girdi!$C:$C;MATCH($A34;Event_Girdi!$A:$A;0))<=Hafta_Ozet!$C5;INDEX(Event_Girdi!$D:$D;MATCH($A34;Event_Girdi!$A:$A;0))>=Hafta_Ozet!$B5);"ACTIVE";""))) | H34: =IF($A34="";"";IF(Hafta_Ozet!$B6="";"";IF(AND(INDEX(Event_Girdi!$C:$C;MATCH($A34;Event_Girdi!$A:$A;0))<=Hafta_Ozet!$C6;INDEX(Event_Girdi!$D:$D;MATCH($A34;Event_Girdi!$A:$A;0))>=Hafta_Ozet!$B6);"ACTIVE";""))) | I34: =IF($A34="";"";IF(Hafta_Ozet!$B7="";"";IF(AND(INDEX(Event_Girdi!$C:$C;MATCH($A34;Event_Girdi!$A:$A;0))<=Hafta_Ozet!$C7;INDEX(Event_Girdi!$D:$D;MATCH($A34;Event_Girdi!$A:$A;0))>=Hafta_Ozet!$B7);"ACTIVE";""))) | J34: =IF($A34="";"";IF(Hafta_Ozet!$B8="";"";IF(AND(INDEX(Event_Girdi!$C:$C;MATCH($A34;Event_Girdi!$A:$A;0))<=Hafta_Ozet!$C8;INDEX(Event_Girdi!$D:$D;MATCH($A34;Event_Girdi!$A:$A;0))>=Hafta_Ozet!$B8);"ACTIVE";""))) | K34: =IF($A34="";"";IF(Hafta_Ozet!$B9="";"";IF(AND(INDEX(Event_Girdi!$C:$C;MATCH($A34;Event_Girdi!$A:$A;0))<=Hafta_Ozet!$C9;INDEX(Event_Girdi!$D:$D;MATCH($A34;Event_Girdi!$A:$A;0))>=Hafta_Ozet!$B9);"ACTIVE";""))) | L34: =IF($A34="";"";IF(Hafta_Ozet!$B10="";"";IF(AND(INDEX(Event_Girdi!$C:$C;MATCH($A34;Event_Girdi!$A:$A;0))<=Hafta_Ozet!$C10;INDEX(Event_Girdi!$D:$D;MATCH($A34;Event_Girdi!$A:$A;0))>=Hafta_Ozet!$B10);"ACTIVE";""))) | M34: =IF($A34="";"";IF(Hafta_Ozet!$B11="";"";IF(AND(INDEX(Event_Girdi!$C:$C;MATCH($A34;Event_Girdi!$A:$A;0))<=Hafta_Ozet!$C11;INDEX(Event_Girdi!$D:$D;MATCH($A34;Event_Girdi!$A:$A;0))>=Hafta_Ozet!$B11);"ACTIVE";""))) | N34: =IF($A34="";"";IF(Hafta_Ozet!$B12="";"";IF(AND(INDEX(Event_Girdi!$C:$C;MATCH($A34;Event_Girdi!$A:$A;0))<=Hafta_Ozet!$C12;INDEX(Event_Girdi!$D:$D;MATCH($A34;Event_Girdi!$A:$A;0))>=Hafta_Ozet!$B12);"ACTIVE";""))) | O34: =IF($A34="";"";IF(Hafta_Ozet!$B13="";"";IF(AND(INDEX(Event_Girdi!$C:$C;MATCH($A34;Event_Girdi!$A:$A;0))<=Hafta_Ozet!$C13;INDEX(Event_Girdi!$D:$D;MATCH($A34;Event_Girdi!$A:$A;0))>=Hafta_Ozet!$B13);"ACTIVE";""))) | P34: =IF($A34="";"";IF(Hafta_Ozet!$B14="";"";IF(AND(INDEX(Event_Girdi!$C:$C;MATCH($A34;Event_Girdi!$A:$A;0))<=Hafta_Ozet!$C14;INDEX(Event_Girdi!$D:$D;MATCH($A34;Event_Girdi!$A:$A;0))>=Hafta_Ozet!$B14);"ACTIVE";""))) | Q34: =IF($A34="";"";IF(Hafta_Ozet!$B15="";"";IF(AND(INDEX(Event_Girdi!$C:$C;MATCH($A34;Event_Girdi!$A:$A;0))<=Hafta_Ozet!$C15;INDEX(Event_Girdi!$D:$D;MATCH($A34;Event_Girdi!$A:$A;0))>=Hafta_Ozet!$B15);"ACTIVE";""))) | R34: =IF($A34="";"";IF(Hafta_Ozet!$B16="";"";IF(AND(INDEX(Event_Girdi!$C:$C;MATCH($A34;Event_Girdi!$A:$A;0))<=Hafta_Ozet!$C16;INDEX(Event_Girdi!$D:$D;MATCH($A34;Event_Girdi!$A:$A;0))>=Hafta_Ozet!$B16);"ACTIVE";""))) | S34: =IF($A34="";"";IF(Hafta_Ozet!$B17="";"";IF(AND(INDEX(Event_Girdi!$C:$C;MATCH($A34;Event_Girdi!$A:$A;0))<=Hafta_Ozet!$C17;INDEX(Event_Girdi!$D:$D;MATCH($A34;Event_Girdi!$A:$A;0))>=Hafta_Ozet!$B17);"ACTIVE";""))) | T34: =IF($A34="";"";IF(Hafta_Ozet!$B18="";"";IF(AND(INDEX(Event_Girdi!$C:$C;MATCH($A34;Event_Girdi!$A:$A;0))<=Hafta_Ozet!$C18;INDEX(Event_Girdi!$D:$D;MATCH($A34;Event_Girdi!$A:$A;0))>=Hafta_Ozet!$B18);"ACTIVE";""))) | U34: =IF($A34="";"";IF(Hafta_Ozet!$B19="";"";IF(AND(INDEX(Event_Girdi!$C:$C;MATCH($A34;Event_Girdi!$A:$A;0))<=Hafta_Ozet!$C19;INDEX(Event_Girdi!$D:$D;MATCH($A34;Event_Girdi!$A:$A;0))>=Hafta_Ozet!$B19);"ACTIVE";""))) | V34: =IF($A34="";"";IF(Hafta_Ozet!$B20="";"";IF(AND(INDEX(Event_Girdi!$C:$C;MATCH($A34;Event_Girdi!$A:$A;0))<=Hafta_Ozet!$C20;INDEX(Event_Girdi!$D:$D;MATCH($A34;Event_Girdi!$A:$A;0))>=Hafta_Ozet!$B20);"ACTIVE";""))) | W34: =IF($A34="";"";IF(Hafta_Ozet!$B21="";"";IF(AND(INDEX(Event_Girdi!$C:$C;MATCH($A34;Event_Girdi!$A:$A;0))<=Hafta_Ozet!$C21;INDEX(Event_Girdi!$D:$D;MATCH($A34;Event_Girdi!$A:$A;0))>=Hafta_Ozet!$B21);"ACTIVE";"")))
A35: =IFERROR(INDEX(FILTER(Event_Girdi!$A$2:$A;Event_Girdi!$G$2:$G="Evet");4);"") | B35: =IF($A35="";"";INDEX(Event_Girdi!$B:$B;MATCH($A35;Event_Girdi!$A:$A;0))) | C35: =IF($A35="";"";INDEX(Event_Girdi!$E:$E;MATCH($A35;Event_Girdi!$A:$A;0))) | D35: =IF($A35="";"";IF(Hafta_Ozet!$B2="";"";IF(AND(INDEX(Event_Girdi!$C:$C;MATCH($A35;Event_Girdi!$A:$A;0))<=Hafta_Ozet!$C2;INDEX(Event_Girdi!$D:$D;MATCH($A35;Event_Girdi!$A:$A;0))>=Hafta_Ozet!$B2);"ACTIVE";""))) | E35: =IF($A35="";"";IF(Hafta_Ozet!$B3="";"";IF(AND(INDEX(Event_Girdi!$C:$C;MATCH($A35;Event_Girdi!$A:$A;0))<=Hafta_Ozet!$C3;INDEX(Event_Girdi!$D:$D;MATCH($A35;Event_Girdi!$A:$A;0))>=Hafta_Ozet!$B3);"ACTIVE";""))) | F35: =IF($A35="";"";IF(Hafta_Ozet!$B4="";"";IF(AND(INDEX(Event_Girdi!$C:$C;MATCH($A35;Event_Girdi!$A:$A;0))<=Hafta_Ozet!$C4;INDEX(Event_Girdi!$D:$D;MATCH($A35;Event_Girdi!$A:$A;0))>=Hafta_Ozet!$B4);"ACTIVE";""))) | G35: =IF($A35="";"";IF(Hafta_Ozet!$B5="";"";IF(AND(INDEX(Event_Girdi!$C:$C;MATCH($A35;Event_Girdi!$A:$A;0))<=Hafta_Ozet!$C5;INDEX(Event_Girdi!$D:$D;MATCH($A35;Event_Girdi!$A:$A;0))>=Hafta_Ozet!$B5);"ACTIVE";""))) | H35: =IF($A35="";"";IF(Hafta_Ozet!$B6="";"";IF(AND(INDEX(Event_Girdi!$C:$C;MATCH($A35;Event_Girdi!$A:$A;0))<=Hafta_Ozet!$C6;INDEX(Event_Girdi!$D:$D;MATCH($A35;Event_Girdi!$A:$A;0))>=Hafta_Ozet!$B6);"ACTIVE";""))) | I35: =IF($A35="";"";IF(Hafta_Ozet!$B7="";"";IF(AND(INDEX(Event_Girdi!$C:$C;MATCH($A35;Event_Girdi!$A:$A;0))<=Hafta_Ozet!$C7;INDEX(Event_Girdi!$D:$D;MATCH($A35;Event_Girdi!$A:$A;0))>=Hafta_Ozet!$B7);"ACTIVE";""))) | J35: =IF($A35="";"";IF(Hafta_Ozet!$B8="";"";IF(AND(INDEX(Event_Girdi!$C:$C;MATCH($A35;Event_Girdi!$A:$A;0))<=Hafta_Ozet!$C8;INDEX(Event_Girdi!$D:$D;MATCH($A35;Event_Girdi!$A:$A;0))>=Hafta_Ozet!$B8);"ACTIVE";""))) | K35: =IF($A35="";"";IF(Hafta_Ozet!$B9="";"";IF(AND(INDEX(Event_Girdi!$C:$C;MATCH($A35;Event_Girdi!$A:$A;0))<=Hafta_Ozet!$C9;INDEX(Event_Girdi!$D:$D;MATCH($A35;Event_Girdi!$A:$A;0))>=Hafta_Ozet!$B9);"ACTIVE";""))) | L35: =IF($A35="";"";IF(Hafta_Ozet!$B10="";"";IF(AND(INDEX(Event_Girdi!$C:$C;MATCH($A35;Event_Girdi!$A:$A;0))<=Hafta_Ozet!$C10;INDEX(Event_Girdi!$D:$D;MATCH($A35;Event_Girdi!$A:$A;0))>=Hafta_Ozet!$B10);"ACTIVE";""))) | M35: =IF($A35="";"";IF(Hafta_Ozet!$B11="";"";IF(AND(INDEX(Event_Girdi!$C:$C;MATCH($A35;Event_Girdi!$A:$A;0))<=Hafta_Ozet!$C11;INDEX(Event_Girdi!$D:$D;MATCH($A35;Event_Girdi!$A:$A;0))>=Hafta_Ozet!$B11);"ACTIVE";""))) | N35: =IF($A35="";"";IF(Hafta_Ozet!$B12="";"";IF(AND(INDEX(Event_Girdi!$C:$C;MATCH($A35;Event_Girdi!$A:$A;0))<=Hafta_Ozet!$C12;INDEX(Event_Girdi!$D:$D;MATCH($A35;Event_Girdi!$A:$A;0))>=Hafta_Ozet!$B12);"ACTIVE";""))) | O35: =IF($A35="";"";IF(Hafta_Ozet!$B13="";"";IF(AND(INDEX(Event_Girdi!$C:$C;MATCH($A35;Event_Girdi!$A:$A;0))<=Hafta_Ozet!$C13;INDEX(Event_Girdi!$D:$D;MATCH($A35;Event_Girdi!$A:$A;0))>=Hafta_Ozet!$B13);"ACTIVE";""))) | P35: =IF($A35="";"";IF(Hafta_Ozet!$B14="";"";IF(AND(INDEX(Event_Girdi!$C:$C;MATCH($A35;Event_Girdi!$A:$A;0))<=Hafta_Ozet!$C14;INDEX(Event_Girdi!$D:$D;MATCH($A35;Event_Girdi!$A:$A;0))>=Hafta_Ozet!$B14);"ACTIVE";""))) | Q35: =IF($A35="";"";IF(Hafta_Ozet!$B15="";"";IF(AND(INDEX(Event_Girdi!$C:$C;MATCH($A35;Event_Girdi!$A:$A;0))<=Hafta_Ozet!$C15;INDEX(Event_Girdi!$D:$D;MATCH($A35;Event_Girdi!$A:$A;0))>=Hafta_Ozet!$B15);"ACTIVE";""))) | R35: =IF($A35="";"";IF(Hafta_Ozet!$B16="";"";IF(AND(INDEX(Event_Girdi!$C:$C;MATCH($A35;Event_Girdi!$A:$A;0))<=Hafta_Ozet!$C16;INDEX(Event_Girdi!$D:$D;MATCH($A35;Event_Girdi!$A:$A;0))>=Hafta_Ozet!$B16);"ACTIVE";""))) | S35: =IF($A35="";"";IF(Hafta_Ozet!$B17="";"";IF(AND(INDEX(Event_Girdi!$C:$C;MATCH($A35;Event_Girdi!$A:$A;0))<=Hafta_Ozet!$C17;INDEX(Event_Girdi!$D:$D;MATCH($A35;Event_Girdi!$A:$A;0))>=Hafta_Ozet!$B17);"ACTIVE";""))) | T35: =IF($A35="";"";IF(Hafta_Ozet!$B18="";"";IF(AND(INDEX(Event_Girdi!$C:$C;MATCH($A35;Event_Girdi!$A:$A;0))<=Hafta_Ozet!$C18;INDEX(Event_Girdi!$D:$D;MATCH($A35;Event_Girdi!$A:$A;0))>=Hafta_Ozet!$B18);"ACTIVE";""))) | U35: =IF($A35="";"";IF(Hafta_Ozet!$B19="";"";IF(AND(INDEX(Event_Girdi!$C:$C;MATCH($A35;Event_Girdi!$A:$A;0))<=Hafta_Ozet!$C19;INDEX(Event_Girdi!$D:$D;MATCH($A35;Event_Girdi!$A:$A;0))>=Hafta_Ozet!$B19);"ACTIVE";""))) | V35: =IF($A35="";"";IF(Hafta_Ozet!$B20="";"";IF(AND(INDEX(Event_Girdi!$C:$C;MATCH($A35;Event_Girdi!$A:$A;0))<=Hafta_Ozet!$C20;INDEX(Event_Girdi!$D:$D;MATCH($A35;Event_Girdi!$A:$A;0))>=Hafta_Ozet!$B20);"ACTIVE";""))) | W35: =IF($A35="";"";IF(Hafta_Ozet!$B21="";"";IF(AND(INDEX(Event_Girdi!$C:$C;MATCH($A35;Event_Girdi!$A:$A;0))<=Hafta_Ozet!$C21;INDEX(Event_Girdi!$D:$D;MATCH($A35;Event_Girdi!$A:$A;0))>=Hafta_Ozet!$B21);"ACTIVE";"")))
A36: =IFERROR(INDEX(FILTER(Event_Girdi!$A$2:$A;Event_Girdi!$G$2:$G="Evet");5);"") | B36: =IF($A36="";"";INDEX(Event_Girdi!$B:$B;MATCH($A36;Event_Girdi!$A:$A;0))) | C36: =IF($A36="";"";INDEX(Event_Girdi!$E:$E;MATCH($A36;Event_Girdi!$A:$A;0))) | D36: =IF($A36="";"";IF(Hafta_Ozet!$B2="";"";IF(AND(INDEX(Event_Girdi!$C:$C;MATCH($A36;Event_Girdi!$A:$A;0))<=Hafta_Ozet!$C2;INDEX(Event_Girdi!$D:$D;MATCH($A36;Event_Girdi!$A:$A;0))>=Hafta_Ozet!$B2);"ACTIVE";""))) | E36: =IF($A36="";"";IF(Hafta_Ozet!$B3="";"";IF(AND(INDEX(Event_Girdi!$C:$C;MATCH($A36;Event_Girdi!$A:$A;0))<=Hafta_Ozet!$C3;INDEX(Event_Girdi!$D:$D;MATCH($A36;Event_Girdi!$A:$A;0))>=Hafta_Ozet!$B3);"ACTIVE";""))) | F36: =IF($A36="";"";IF(Hafta_Ozet!$B4="";"";IF(AND(INDEX(Event_Girdi!$C:$C;MATCH($A36;Event_Girdi!$A:$A;0))<=Hafta_Ozet!$C4;INDEX(Event_Girdi!$D:$D;MATCH($A36;Event_Girdi!$A:$A;0))>=Hafta_Ozet!$B4);"ACTIVE";""))) | G36: =IF($A36="";"";IF(Hafta_Ozet!$B5="";"";IF(AND(INDEX(Event_Girdi!$C:$C;MATCH($A36;Event_Girdi!$A:$A;0))<=Hafta_Ozet!$C5;INDEX(Event_Girdi!$D:$D;MATCH($A36;Event_Girdi!$A:$A;0))>=Hafta_Ozet!$B5);"ACTIVE";""))) | H36: =IF($A36="";"";IF(Hafta_Ozet!$B6="";"";IF(AND(INDEX(Event_Girdi!$C:$C;MATCH($A36;Event_Girdi!$A:$A;0))<=Hafta_Ozet!$C6;INDEX(Event_Girdi!$D:$D;MATCH($A36;Event_Girdi!$A:$A;0))>=Hafta_Ozet!$B6);"ACTIVE";""))) | I36: =IF($A36="";"";IF(Hafta_Ozet!$B7="";"";IF(AND(INDEX(Event_Girdi!$C:$C;MATCH($A36;Event_Girdi!$A:$A;0))<=Hafta_Ozet!$C7;INDEX(Event_Girdi!$D:$D;MATCH($A36;Event_Girdi!$A:$A;0))>=Hafta_Ozet!$B7);"ACTIVE";""))) | J36: =IF($A36="";"";IF(Hafta_Ozet!$B8="";"";IF(AND(INDEX(Event_Girdi!$C:$C;MATCH($A36;Event_Girdi!$A:$A;0))<=Hafta_Ozet!$C8;INDEX(Event_Girdi!$D:$D;MATCH($A36;Event_Girdi!$A:$A;0))>=Hafta_Ozet!$B8);"ACTIVE";""))) | K36: =IF($A36="";"";IF(Hafta_Ozet!$B9="";"";IF(AND(INDEX(Event_Girdi!$C:$C;MATCH($A36;Event_Girdi!$A:$A;0))<=Hafta_Ozet!$C9;INDEX(Event_Girdi!$D:$D;MATCH($A36;Event_Girdi!$A:$A;0))>=Hafta_Ozet!$B9);"ACTIVE";""))) | L36: =IF($A36="";"";IF(Hafta_Ozet!$B10="";"";IF(AND(INDEX(Event_Girdi!$C:$C;MATCH($A36;Event_Girdi!$A:$A;0))<=Hafta_Ozet!$C10;INDEX(Event_Girdi!$D:$D;MATCH($A36;Event_Girdi!$A:$A;0))>=Hafta_Ozet!$B10);"ACTIVE";""))) | M36: =IF($A36="";"";IF(Hafta_Ozet!$B11="";"";IF(AND(INDEX(Event_Girdi!$C:$C;MATCH($A36;Event_Girdi!$A:$A;0))<=Hafta_Ozet!$C11;INDEX(Event_Girdi!$D:$D;MATCH($A36;Event_Girdi!$A:$A;0))>=Hafta_Ozet!$B11);"ACTIVE";""))) | N36: =IF($A36="";"";IF(Hafta_Ozet!$B12="";"";IF(AND(INDEX(Event_Girdi!$C:$C;MATCH($A36;Event_Girdi!$A:$A;0))<=Hafta_Ozet!$C12;INDEX(Event_Girdi!$D:$D;MATCH($A36;Event_Girdi!$A:$A;0))>=Hafta_Ozet!$B12);"ACTIVE";""))) | O36: =IF($A36="";"";IF(Hafta_Ozet!$B13="";"";IF(AND(INDEX(Event_Girdi!$C:$C;MATCH($A36;Event_Girdi!$A:$A;0))<=Hafta_Ozet!$C13;INDEX(Event_Girdi!$D:$D;MATCH($A36;Event_Girdi!$A:$A;0))>=Hafta_Ozet!$B13);"ACTIVE";""))) | P36: =IF($A36="";"";IF(Hafta_Ozet!$B14="";"";IF(AND(INDEX(Event_Girdi!$C:$C;MATCH($A36;Event_Girdi!$A:$A;0))<=Hafta_Ozet!$C14;INDEX(Event_Girdi!$D:$D;MATCH($A36;Event_Girdi!$A:$A;0))>=Hafta_Ozet!$B14);"ACTIVE";""))) | Q36: =IF($A36="";"";IF(Hafta_Ozet!$B15="";"";IF(AND(INDEX(Event_Girdi!$C:$C;MATCH($A36;Event_Girdi!$A:$A;0))<=Hafta_Ozet!$C15;INDEX(Event_Girdi!$D:$D;MATCH($A36;Event_Girdi!$A:$A;0))>=Hafta_Ozet!$B15);"ACTIVE";""))) | R36: =IF($A36="";"";IF(Hafta_Ozet!$B16="";"";IF(AND(INDEX(Event_Girdi!$C:$C;MATCH($A36;Event_Girdi!$A:$A;0))<=Hafta_Ozet!$C16;INDEX(Event_Girdi!$D:$D;MATCH($A36;Event_Girdi!$A:$A;0))>=Hafta_Ozet!$B16);"ACTIVE";""))) | S36: =IF($A36="";"";IF(Hafta_Ozet!$B17="";"";IF(AND(INDEX(Event_Girdi!$C:$C;MATCH($A36;Event_Girdi!$A:$A;0))<=Hafta_Ozet!$C17;INDEX(Event_Girdi!$D:$D;MATCH($A36;Event_Girdi!$A:$A;0))>=Hafta_Ozet!$B17);"ACTIVE";""))) | T36: =IF($A36="";"";IF(Hafta_Ozet!$B18="";"";IF(AND(INDEX(Event_Girdi!$C:$C;MATCH($A36;Event_Girdi!$A:$A;0))<=Hafta_Ozet!$C18;INDEX(Event_Girdi!$D:$D;MATCH($A36;Event_Girdi!$A:$A;0))>=Hafta_Ozet!$B18);"ACTIVE";""))) | U36: =IF($A36="";"";IF(Hafta_Ozet!$B19="";"";IF(AND(INDEX(Event_Girdi!$C:$C;MATCH($A36;Event_Girdi!$A:$A;0))<=Hafta_Ozet!$C19;INDEX(Event_Girdi!$D:$D;MATCH($A36;Event_Girdi!$A:$A;0))>=Hafta_Ozet!$B19);"ACTIVE";""))) | V36: =IF($A36="";"";IF(Hafta_Ozet!$B20="";"";IF(AND(INDEX(Event_Girdi!$C:$C;MATCH($A36;Event_Girdi!$A:$A;0))<=Hafta_Ozet!$C20;INDEX(Event_Girdi!$D:$D;MATCH($A36;Event_Girdi!$A:$A;0))>=Hafta_Ozet!$B20);"ACTIVE";""))) | W36: =IF($A36="";"";IF(Hafta_Ozet!$B21="";"";IF(AND(INDEX(Event_Girdi!$C:$C;MATCH($A36;Event_Girdi!$A:$A;0))<=Hafta_Ozet!$C21;INDEX(Event_Girdi!$D:$D;MATCH($A36;Event_Girdi!$A:$A;0))>=Hafta_Ozet!$B21);"ACTIVE";"")))
A37: =IFERROR(INDEX(FILTER(Event_Girdi!$A$2:$A;Event_Girdi!$G$2:$G="Evet");6);"") | B37: =IF($A37="";"";INDEX(Event_Girdi!$B:$B;MATCH($A37;Event_Girdi!$A:$A;0))) | C37: =IF($A37="";"";INDEX(Event_Girdi!$E:$E;MATCH($A37;Event_Girdi!$A:$A;0))) | D37: =IF($A37="";"";IF(Hafta_Ozet!$B2="";"";IF(AND(INDEX(Event_Girdi!$C:$C;MATCH($A37;Event_Girdi!$A:$A;0))<=Hafta_Ozet!$C2;INDEX(Event_Girdi!$D:$D;MATCH($A37;Event_Girdi!$A:$A;0))>=Hafta_Ozet!$B2);"ACTIVE";""))) | E37: =IF($A37="";"";IF(Hafta_Ozet!$B3="";"";IF(AND(INDEX(Event_Girdi!$C:$C;MATCH($A37;Event_Girdi!$A:$A;0))<=Hafta_Ozet!$C3;INDEX(Event_Girdi!$D:$D;MATCH($A37;Event_Girdi!$A:$A;0))>=Hafta_Ozet!$B3);"ACTIVE";""))) | F37: =IF($A37="";"";IF(Hafta_Ozet!$B4="";"";IF(AND(INDEX(Event_Girdi!$C:$C;MATCH($A37;Event_Girdi!$A:$A;0))<=Hafta_Ozet!$C4;INDEX(Event_Girdi!$D:$D;MATCH($A37;Event_Girdi!$A:$A;0))>=Hafta_Ozet!$B4);"ACTIVE";""))) | G37: =IF($A37="";"";IF(Hafta_Ozet!$B5="";"";IF(AND(INDEX(Event_Girdi!$C:$C;MATCH($A37;Event_Girdi!$A:$A;0))<=Hafta_Ozet!$C5;INDEX(Event_Girdi!$D:$D;MATCH($A37;Event_Girdi!$A:$A;0))>=Hafta_Ozet!$B5);"ACTIVE";""))) | H37: =IF($A37="";"";IF(Hafta_Ozet!$B6="";"";IF(AND(INDEX(Event_Girdi!$C:$C;MATCH($A37;Event_Girdi!$A:$A;0))<=Hafta_Ozet!$C6;INDEX(Event_Girdi!$D:$D;MATCH($A37;Event_Girdi!$A:$A;0))>=Hafta_Ozet!$B6);"ACTIVE";""))) | I37: =IF($A37="";"";IF(Hafta_Ozet!$B7="";"";IF(AND(INDEX(Event_Girdi!$C:$C;MATCH($A37;Event_Girdi!$A:$A;0))<=Hafta_Ozet!$C7;INDEX(Event_Girdi!$D:$D;MATCH($A37;Event_Girdi!$A:$A;0))>=Hafta_Ozet!$B7);"ACTIVE";""))) | J37: =IF($A37="";"";IF(Hafta_Ozet!$B8="";"";IF(AND(INDEX(Event_Girdi!$C:$C;MATCH($A37;Event_Girdi!$A:$A;0))<=Hafta_Ozet!$C8;INDEX(Event_Girdi!$D:$D;MATCH($A37;Event_Girdi!$A:$A;0))>=Hafta_Ozet!$B8);"ACTIVE";""))) | K37: =IF($A37="";"";IF(Hafta_Ozet!$B9="";"";IF(AND(INDEX(Event_Girdi!$C:$C;MATCH($A37;Event_Girdi!$A:$A;0))<=Hafta_Ozet!$C9;INDEX(Event_Girdi!$D:$D;MATCH($A37;Event_Girdi!$A:$A;0))>=Hafta_Ozet!$B9);"ACTIVE";""))) | L37: =IF($A37="";"";IF(Hafta_Ozet!$B10="";"";IF(AND(INDEX(Event_Girdi!$C:$C;MATCH($A37;Event_Girdi!$A:$A;0))<=Hafta_Ozet!$C10;INDEX(Event_Girdi!$D:$D;MATCH($A37;Event_Girdi!$A:$A;0))>=Hafta_Ozet!$B10);"ACTIVE";""))) | M37: =IF($A37="";"";IF(Hafta_Ozet!$B11="";"";IF(AND(INDEX(Event_Girdi!$C:$C;MATCH($A37;Event_Girdi!$A:$A;0))<=Hafta_Ozet!$C11;INDEX(Event_Girdi!$D:$D;MATCH($A37;Event_Girdi!$A:$A;0))>=Hafta_Ozet!$B11);"ACTIVE";""))) | N37: =IF($A37="";"";IF(Hafta_Ozet!$B12="";"";IF(AND(INDEX(Event_Girdi!$C:$C;MATCH($A37;Event_Girdi!$A:$A;0))<=Hafta_Ozet!$C12;INDEX(Event_Girdi!$D:$D;MATCH($A37;Event_Girdi!$A:$A;0))>=Hafta_Ozet!$B12);"ACTIVE";""))) | O37: =IF($A37="";"";IF(Hafta_Ozet!$B13="";"";IF(AND(INDEX(Event_Girdi!$C:$C;MATCH($A37;Event_Girdi!$A:$A;0))<=Hafta_Ozet!$C13;INDEX(Event_Girdi!$D:$D;MATCH($A37;Event_Girdi!$A:$A;0))>=Hafta_Ozet!$B13);"ACTIVE";""))) | P37: =IF($A37="";"";IF(Hafta_Ozet!$B14="";"";IF(AND(INDEX(Event_Girdi!$C:$C;MATCH($A37;Event_Girdi!$A:$A;0))<=Hafta_Ozet!$C14;INDEX(Event_Girdi!$D:$D;MATCH($A37;Event_Girdi!$A:$A;0))>=Hafta_Ozet!$B14);"ACTIVE";""))) | Q37: =IF($A37="";"";IF(Hafta_Ozet!$B15="";"";IF(AND(INDEX(Event_Girdi!$C:$C;MATCH($A37;Event_Girdi!$A:$A;0))<=Hafta_Ozet!$C15;INDEX(Event_Girdi!$D:$D;MATCH($A37;Event_Girdi!$A:$A;0))>=Hafta_Ozet!$B15);"ACTIVE";""))) | R37: =IF($A37="";"";IF(Hafta_Ozet!$B16="";"";IF(AND(INDEX(Event_Girdi!$C:$C;MATCH($A37;Event_Girdi!$A:$A;0))<=Hafta_Ozet!$C16;INDEX(Event_Girdi!$D:$D;MATCH($A37;Event_Girdi!$A:$A;0))>=Hafta_Ozet!$B16);"ACTIVE";""))) | S37: =IF($A37="";"";IF(Hafta_Ozet!$B17="";"";IF(AND(INDEX(Event_Girdi!$C:$C;MATCH($A37;Event_Girdi!$A:$A;0))<=Hafta_Ozet!$C17;INDEX(Event_Girdi!$D:$D;MATCH($A37;Event_Girdi!$A:$A;0))>=Hafta_Ozet!$B17);"ACTIVE";""))) | T37: =IF($A37="";"";IF(Hafta_Ozet!$B18="";"";IF(AND(INDEX(Event_Girdi!$C:$C;MATCH($A37;Event_Girdi!$A:$A;0))<=Hafta_Ozet!$C18;INDEX(Event_Girdi!$D:$D;MATCH($A37;Event_Girdi!$A:$A;0))>=Hafta_Ozet!$B18);"ACTIVE";""))) | U37: =IF($A37="";"";IF(Hafta_Ozet!$B19="";"";IF(AND(INDEX(Event_Girdi!$C:$C;MATCH($A37;Event_Girdi!$A:$A;0))<=Hafta_Ozet!$C19;INDEX(Event_Girdi!$D:$D;MATCH($A37;Event_Girdi!$A:$A;0))>=Hafta_Ozet!$B19);"ACTIVE";""))) | V37: =IF($A37="";"";IF(Hafta_Ozet!$B20="";"";IF(AND(INDEX(Event_Girdi!$C:$C;MATCH($A37;Event_Girdi!$A:$A;0))<=Hafta_Ozet!$C20;INDEX(Event_Girdi!$D:$D;MATCH($A37;Event_Girdi!$A:$A;0))>=Hafta_Ozet!$B20);"ACTIVE";""))) | W37: =IF($A37="";"";IF(Hafta_Ozet!$B21="";"";IF(AND(INDEX(Event_Girdi!$C:$C;MATCH($A37;Event_Girdi!$A:$A;0))<=Hafta_Ozet!$C21;INDEX(Event_Girdi!$D:$D;MATCH($A37;Event_Girdi!$A:$A;0))>=Hafta_Ozet!$B21);"ACTIVE";"")))
